Workbook
Name NgayQua: 'Khai báo'!$B$5
Name SoNgay: 'Khai báo'!$B$6
Name MucTieuTC: 'Khai báo'!$B$7
Name CoRT: 'Khai báo'!$B$8
Name CoRTNhom: 'Khai báo'!$B$9

Sheet Hướng dẫn
B2: FILE ĐỔ SỐ TAY — Realtime · Lũy kế · Chi tiết NV (không cần AutoBI)
B4: ĐẦU THÁNG (1 lần)
B5: 1. Sheet "Khai báo": tên cụm, tháng, mục tiêu trả chậm; tên gọn + tên trên BI + target tháng từng siêu thị.
B6: 2. Nhóm thi đua: tên gọn, tên chương trình trên BI (bỏ phần "T10 - "), loại Chính / Vượt trội, target từng shop (trống = lấy target BI).
B7: 3. Nhân viên: mã NV, họ tên, siêu thị 1/2/3, % phân bổ (trống = chia đều phần còn lại).
B9: MỖI NGÀY
B10: 4. Trang Thi đua: chọn các siêu thị · Lũy kế · Danh sách · Tải lại · bấm "Chép bảng" → dán vào ô A1 sheet "Dán TĐ lũy kế".
B11: 5. Cùng trang, bấm vào TÊN SIÊU THỊ để ra từng nhân viên · "Chép bảng" → dán A1 sheet "Dán TĐ nhân viên" (siêu thị thứ 2 dán tiếp ngay dưới).
B12: 6. Muốn có Realtime: chọn Realtime · "Chép bảng" → dán A1 sheet "Dán TĐ realtime".
B13: 7. Trang Doanh thu hợp nhất (DT quy đổi): tab Nhân viên · bôi đen cả bảng → dán A1 sheet "Dán DT nhân viên" (Realtime → "Dán DT NV realtime").
B14: 8. Sheet "Nhập số": gõ DT QĐ lũy kế, DT thực, % trả chậm (và realtime nếu có) của từng siêu thị.
B15: 9. Mở sheet Realtime / Lũy kế / Chi tiết NV, chọn ô "Xem" (Tổng cụm hoặc từng siêu thị). Mọi số tự tính, tự xếp, tự tô màu.
... B22: • Sheet "Tính" là bảng tính trung gian, không sửa.

Sheet Khai báo
A1: KHAI BÁO — làm 1 lần đầu tháng (ô vàng là ô nhập)
A3: Tên cụm / báo cáo
A4: Tháng | B4: 10/2026
A5: Ngày đã qua (lũy kế đến hết ngày) | B5: =MAX(1,DAY(TODAY())-1) | C5: tự tính theo hôm nay — gõ số để ghi đè
A6: Số ngày trong tháng | B6: =DAY(EOMONTH(TODAY(),0))
A7: Mục tiêu trả chậm | B7: 0.3
A8: Có doanh thu realtime hôm nay (1 = có) | B8: =IF(SUM('Nhập số'!E4:E7)>0,1,0) | C8: tự nhận khi Nhập số có DT realtime
A9: Có số nhóm hàng realtime (1 = có) | B9: =IF(COUNTA('Dán TĐ realtime'!A1:A30)>0,1,0)
A11: Siêu thị | B11: Tên gọn (hiện trên báo cáo) | C11: Tên trên BI (đúng như dòng ở bảng Thi đua) | D11: Target tháng (DT QĐ, triệu) | E11: Target ngày (trống = tự chia)
A12: Siêu thị 1
A13: Siêu thị 2
A14: Siêu thị 3
A15: Siêu thị 4
A16: NHÓM THI ĐUA — target trống = lấy target trên BI · DT tính bằng triệu, SL tính bằng cái (như BI)
A17: Nhóm thi đua (tên gọn) | B17: Tên chương trình trên BI (bỏ "T10 - ") | C17: Loại | D17: Target ST1 | E17: Target ST2 | F17: Target ST3 | G17: Target ST4 | H17: Ghi chú
A44: NHÂN VIÊN — % phân bổ trống = chia đều phần còn lại của siêu thị
A45: Mã NV | B45: Họ tên | C45: Siêu thị (1/2/3) | D45: % phân bổ

Sheet Nhập số
A1: NHẬP SỐ DOANH THU MỖI NGÀY (lấy ở trang Doanh thu hợp nhất, chế độ DT quy đổi)
A3: Siêu thị | B3: DT QĐ lũy kế | C3: DT thực lũy kế | D3: % trả chậm lũy kế | E3: DT QĐ realtime hôm nay | F3: DT thực realtime | G3: % trả chậm realtime
A4: =IF('Khai báo'!B12="","",'Khai báo'!B12)
A5: =IF('Khai báo'!B13="","",'Khai báo'!B13)
A6: =IF('Khai báo'!B14="","",'Khai báo'!B14)
A7: =IF('Khai báo'!B15="","",'Khai báo'!B15)
A9: Tiền: triệu đồng · % trả chậm gõ dạng 34% · realtime để trống nếu chưa có số

Sheet Realtime
A1: ="BÁO CÁO REALTIME — "&'Khai báo'!B3&" · "&TEXT(TODAY(),"dd/mm/yyyy") | AZ1: =IFERROR(MATCH($B$2,'Tính'!$B$31:$B$34,0),0)
A2: Xem: | B2: Tổng cụm | F2: ◀ bấm ô vàng để chọn Tổng cụm hoặc từng siêu thị | BA2: Nhóm (view) | BJ2: Thứ tự
BA3: ='Tính'!B3 | BB3: ='Tính'!D3 | BC3: =IF($AZ$1=0,'Tính'!$Z$3,CHOOSE($AZ$1,'Tính'!$G$3,'Tính'!$L$3,'Tính'!$Q$3,'Tính'!$V$3)) | BD3: =IF($AZ$1=0,'Tính'!$Y$3,CHOOSE($AZ$1,'Tính'!$E$3,'Tính'!$J$3,'Tính'!$O$3,'Tính'!$T$3)) | BE3: =IF($AZ$1=0,'Tính'!$AB$3,CHOOSE($AZ$1,'Tính'!$I$3,'Tính'!$N$3,'Tính'!$S$3,'Tính'!$X$3)) | BF3: =IF($AZ$1=0,'Tính'!$AA$3,CHOOSE($AZ$1,'Tính'!$H$3,'Tính'!$M$3,'Tính'!$R$3,'Tính'!$W$3)) | BG3: =IF(BC3>0,BD3/NgayQua*SoNgay/BC3,IF(BD3>0,1,0)) | BH3: =IF(CoRTNhom=1,IF(BC3>0,(BD3+BF3)/(NgayQua+1)*SoNgay/BC3,IF(BD3+BF3>0,1,0)),BG3) | BI3: =IF(BA3="",-1,IF(BB3="Chính",1000,0)+BH3+(20-1)/100000) | BJ3: =IF(LARGE($BI$3:$BI$22,1)<0,"",MATCH(LARGE($BI$3:$BI$22,1),$BI$3:$BI$22,0)) | CA3: 1 | CB3: =IF('Tính'!B39="",0,IF(OR($AZ$1=0,'Tính'!D39=$AZ$1),1,0)) | CC3: =IF(CB3=1,'Tính'!L39*1000+'Tính'!M39+1+(45-1)/1000000,-1) | CD3: =IF(LARGE($CC$3:$CC$47,1)<0,"",MATCH(LARGE($CC$3:$CC$47,1),$CC$3:$CC$47,0))
A4: Mục tiêu ngày | C4: Thực hiện | G4: Target QĐ | I4: =INDEX('Tính'!$D$31:$D$35,IF($AZ$1=0,5,$AZ$1)) | BA4: ='Tính'!B4 | BB4: ='Tính'!D4 | BC4: =IF($AZ$1=0,'Tính'!$Z$4,CHOOSE($AZ$1,'Tính'!$G$4,'Tính'!$L$4,'Tính'!$Q$4,'Tính'!$V$4)) | BD4: =IF($AZ$1=0,'Tính'!$Y$4,CHOOSE($AZ$1,'Tính'!$E$4,'Tính'!$J$4,'Tính'!$O$4,'Tính'!$T$4)) | BE4: =IF($AZ$1=0,'Tính'!$AB$4,CHOOSE($AZ$1,'Tính'!$I$4,'Tính'!$N$4,'Tính'!$S$4,'Tính'!$X$4)) | BF4: =IF($AZ$1=0,'Tính'!$AA$4,CHOOSE($AZ$1,'Tính'!$H$4,'Tính'!$M$4,'Tính'!$R$4,'Tính'!$W$4)) | BG4: =IF(BC4>0,BD4/NgayQua*SoNgay/BC4,IF(BD4>0,1,0)) | BH4: =IF(CoRTNhom=1,IF(BC4>0,(BD4+BF4)/(NgayQua+1)*SoNgay/BC4,IF(BD4+BF4>0,1,0)),BG4) | BI4: =IF(BA4="",-1,IF(BB4="Chính",1000,0)+BH4+(20-2)/100000) | BJ4: =IF(LARGE($BI$3:$BI$22,2)<0,"",MATCH(LARGE($BI$3:$BI$22,2),$BI$3:$BI$22,0)) | CA4: 2 | CB4: =IF('Tính'!B40="",0,IF(OR($AZ$1=0,'Tính'!D40=$AZ$1),1,0)) | CC4: =IF(CB4=1,'Tính'!L40*1000+'Tính'!M40+1+(45-2)/1000000,-1) | CD4: =IF(LARGE($CC$3:$CC$47,2)<0,"",MATCH(LARGE($CC$3:$CC$47,2),$CC$3:$CC$47,0))
A5: =INDEX('Tính'!$E$31:$E$35,IF($AZ$1=0,5,$AZ$1)) | C5: =INDEX('Tính'!$I$31:$I$35,IF($AZ$1=0,5,$AZ$1)) | G5: Thực hiện QĐ | I5: =INDEX('Tính'!$F$31:$F$35,IF($AZ$1=0,5,$AZ$1)) | BA5: ='Tính'!B5 | BB5: ='Tính'!D5 | BC5: =IF($AZ$1=0,'Tính'!$Z$5,CHOOSE($AZ$1,'Tính'!$G$5,'Tính'!$L$5,'Tính'!$Q$5,'Tính'!$V$5)) | BD5: =IF($AZ$1=0,'Tính'!$Y$5,CHOOSE($AZ$1,'Tính'!$E$5,'Tính'!$J$5,'Tính'!$O$5,'Tính'!$T$5)) | BE5: =IF($AZ$1=0,'Tính'!$AB$5,CHOOSE($AZ$1,'Tính'!$I$5,'Tính'!$N$5,'Tính'!$S$5,'Tính'!$X$5)) | BF5: =IF($AZ$1=0,'Tính'!$AA$5,CHOOSE($AZ$1,'Tính'!$H$5,'Tính'!$M$5,'Tính'!$R$5,'Tính'!$W$5)) | BG5: =IF(BC5>0,BD5/NgayQua*SoNgay/BC5,IF(BD5>0,1,0)) | BH5: =IF(CoRTNhom=1,IF(BC5>0,(BD5+BF5)/(NgayQua+1)*SoNgay/BC5,IF(BD5+BF5>0,1,0)),BG5) | BI5: =IF(BA5="",-1,IF(BB5="Chính",1000,0)+BH5+(20-3)/100000) | BJ5: =IF(LARGE($BI$3:$BI$22,3)<0,"",MATCH(LARGE($BI$3:$BI$22,3),$BI$3:$BI$22,0)) | CA5: 3 | CB5: =IF('Tính'!B41="",0,IF(OR($AZ$1=0,'Tính'!D41=$AZ$1),1,0)) | CC5: =IF(CB5=1,'Tính'!L41*1000+'Tính'!M41+1+(45-3)/1000000,-1) | CD5: =IF(LARGE($CC$3:$CC$47,3)<0,"",MATCH(LARGE($CC$3:$CC$47,3),$CC$3:$CC$47,0))
A6: Hoàn thành | B6: =IF(A5>0,C5/A5,0) | C6: %QĐ | E6: =IFERROR(C5/INDEX('Tính'!$J$31:$J$35,IF($AZ$1=0,5,$AZ$1)),0) | G6: Hoàn thành | I6: =IF(I4>0,I5/I4,0) | K6: Còn lại | L6: =MAX(0,I4-I5) | BA6: ='Tính'!B6 | BB6: ='Tính'!D6 | BC6: =IF($AZ$1=0,'Tính'!$Z$6,CHOOSE($AZ$1,'Tính'!$G$6,'Tính'!$L$6,'Tính'!$Q$6,'Tính'!$V$6)) | BD6: =IF($AZ$1=0,'Tính'!$Y$6,CHOOSE($AZ$1,'Tính'!$E$6,'Tính'!$J$6,'Tính'!$O$6,'Tính'!$T$6)) | BE6: =IF($AZ$1=0,'Tính'!$AB$6,CHOOSE($AZ$1,'Tính'!$I$6,'Tính'!$N$6,'Tính'!$S$6,'Tính'!$X$6)) | BF6: =IF($AZ$1=0,'Tính'!$AA$6,CHOOSE($AZ$1,'Tính'!$H$6,'Tính'!$M$6,'Tính'!$R$6,'Tính'!$W$6)) | BG6: =IF(BC6>0,BD6/NgayQua*SoNgay/BC6,IF(BD6>0,1,0)) | BH6: =IF(CoRTNhom=1,IF(BC6>0,(BD6+BF6)/(NgayQua+1)*SoNgay/BC6,IF(BD6+BF6>0,1,0)),BG6) | BI6: =IF(BA6="",-1,IF(BB6="Chính",1000,0)+BH6+(20-4)/100000) | BJ6: =IF(LARGE($BI$3:$BI$22,4)<0,"",MATCH(LARGE($BI$3:$BI$22,4),$BI$3:$BI$22,0)) | CA6: 4 | CB6: =IF('Tính'!B42="",0,IF(OR($AZ$1=0,'Tính'!D42=$AZ$1),1,0)) | CC6: =IF(CB6=1,'Tính'!L42*1000+'Tính'!M42+1+(45-4)/1000000,-1) | CD6: =IF(LARGE($CC$3:$CC$47,4)<0,"",MATCH(LARGE($CC$3:$CC$47,4),$CC$3:$CC$47,0))
A7: Mục tiêu trả chậm | C7: =MucTieuTC | G7: ☀️ DK ngày mai | I7: =IF(I4>0,IF(CoRT=1,(I5+C5)/(NgayQua+1)*SoNgay/I4,I5/NgayQua*SoNgay/I4),0) | BA7: ='Tính'!B7 | BB7: ='Tính'!D7 | BC7: =IF($AZ$1=0,'Tính'!$Z$7,CHOOSE($AZ$1,'Tính'!$G$7,'Tính'!$L$7,'Tính'!$Q$7,'Tính'!$V$7)) | BD7: =IF($AZ$1=0,'Tính'!$Y$7,CHOOSE($AZ$1,'Tính'!$E$7,'Tính'!$J$7,'Tính'!$O$7,'Tính'!$T$7)) | BE7: =IF($AZ$1=0,'Tính'!$AB$7,CHOOSE($AZ$1,'Tính'!$I$7,'Tính'!$N$7,'Tính'!$S$7,'Tính'!$X$7)) | BF7: =IF($AZ$1=0,'Tính'!$AA$7,CHOOSE($AZ$1,'Tính'!$H$7,'Tính'!$M$7,'Tính'!$R$7,'Tính'!$W$7)) | BG7: =IF(BC7>0,BD7/NgayQua*SoNgay/BC7,IF(BD7>0,1,0)) | BH7: =IF(CoRTNhom=1,IF(BC7>0,(BD7+BF7)/(NgayQua+1)*SoNgay/BC7,IF(BD7+BF7>0,1,0)),BG7) | BI7: =IF(BA7="",-1,IF(BB7="Chính",1000,0)+BH7+(20-5)/100000) | BJ7: =IF(LARGE($BI$3:$BI$22,5)<0,"",MATCH(LARGE($BI$3:$BI$22,5),$BI$3:$BI$22,0)) | CA7: 5 | CB7: =IF('Tính'!B43="",0,IF(OR($AZ$1=0,'Tính'!D43=$AZ$1),1,0)) | CC7: =IF(CB7=1,'Tính'!L43*1000+'Tính'!M43+1+(45-5)/1000000,-1) | CD7: =IF(LARGE($CC$3:$CC$47,5)<0,"",MATCH(LARGE($CC$3:$CC$47,5),$CC$3:$CC$47,0))
A8: Realtime trả chậm | C8: =INDEX('Tính'!$K$31:$K$35,IF($AZ$1=0,5,$AZ$1)) | G8: Lũy kế trả chậm | I8: =INDEX('Tính'!$H$31:$H$35,IF($AZ$1=0,5,$AZ$1)) | K8: %QĐ/thực | L8: =IFERROR(I5/INDEX('Tính'!$G$31:$G$35,IF($AZ$1=0,5,$AZ$1)),0) | BA8: ='Tính'!B8 | BB8: ='Tính'!D8 | BC8: =IF($AZ$1=0,'Tính'!$Z$8,CHOOSE($AZ$1,'Tính'!$G$8,'Tính'!$L$8,'Tính'!$Q$8,'Tính'!$V$8)) | BD8: =IF($AZ$1=0,'Tính'!$Y$8,CHOOSE($AZ$1,'Tính'!$E$8,'Tính'!$J$8,'Tính'!$O$8,'Tính'!$T$8)) | BE8: =IF($AZ$1=0,'Tính'!$AB$8,CHOOSE($AZ$1,'Tính'!$I$8,'Tính'!$N$8,'Tính'!$S$8,'Tính'!$X$8)) | BF8: =IF($AZ$1=0,'Tính'!$AA$8,CHOOSE($AZ$1,'Tính'!$H$8,'Tính'!$M$8,'Tính'!$R$8,'Tính'!$W$8)) | BG8: =IF(BC8>0,BD8/NgayQua*SoNgay/BC8,IF(BD8>0,1,0)) | BH8: =IF(CoRTNhom=1,IF(BC8>0,(BD8+BF8)/(NgayQua+1)*SoNgay/BC8,IF(BD8+BF8>0,1,0)),BG8) | BI8: =IF(BA8="",-1,IF(BB8="Chính",1000,0)+BH8+(20-6)/100000) | BJ8: =IF(LARGE($BI$3:$BI$22,6)<0,"",MATCH(LARGE($BI$3:$BI$22,6),$BI$3:$BI$22,0)) | CA8: 6 | CB8: =IF('Tính'!B44="",0,IF(OR($AZ$1=0,'Tính'!D44=$AZ$1),1,0)) | CC8: =IF(CB8=1,'Tính'!L44*1000+'Tính'!M44+1+(45-6)/1000000,-1) | CD8: =IF(LARGE($CC$3:$CC$47,6)<0,"",MATCH(LARGE($CC$3:$CC$47,6),$CC$3:$CC$47,0))
BA9: ='Tính'!B9 | BB9: ='Tính'!D9 | BC9: =IF($AZ$1=0,'Tính'!$Z$9,CHOOSE($AZ$1,'Tính'!$G$9,'Tính'!$L$9,'Tính'!$Q$9,'Tính'!$V$9)) | BD9: =IF($AZ$1=0,'Tính'!$Y$9,CHOOSE($AZ$1,'Tính'!$E$9,'Tính'!$J$9,'Tính'!$O$9,'Tính'!$T$9)) | BE9: =IF($AZ$1=0,'Tính'!$AB$9,CHOOSE($AZ$1,'Tính'!$I$9,'Tính'!$N$9,'Tính'!$S$9,'Tính'!$X$9)) | BF9: =IF($AZ$1=0,'Tính'!$AA$9,CHOOSE($AZ$1,'Tính'!$H$9,'Tính'!$M$9,'Tính'!$R$9,'Tính'!$W$9)) | BG9: =IF(BC9>0,BD9/NgayQua*SoNgay/BC9,IF(BD9>0,1,0)) | BH9: =IF(CoRTNhom=1,IF(BC9>0,(BD9+BF9)/(NgayQua+1)*SoNgay/BC9,IF(BD9+BF9>0,1,0)),BG9) | BI9: =IF(BA9="",-1,IF(BB9="Chính",1000,0)+BH9+(20-7)/100000) | BJ9: =IF(LARGE($BI$3:$BI$22,7)<0,"",MATCH(LARGE($BI$3:$BI$22,7),$BI$3:$BI$22,0)) | CA9: 7 | CB9: =IF('Tính'!B45="",0,IF(OR($AZ$1=0,'Tính'!D45=$AZ$1),1,0)) | CC9: =IF(CB9=1,'Tính'!L45*1000+'Tính'!M45+1+(45-7)/1000000,-1) | CD9: =IF(LARGE($CC$3:$CC$47,7)<0,"",MATCH(LARGE($CC$3:$CC$47,7),$CC$3:$CC$47,0))
A10: ="Realtime: "&COUNTIF($BA$3:$BA$22,"?*")&" nhóm" | C10: Đạt: | D10: =COUNTIFS(D12:D31,">0",E12:E31,">=0.995") | G10: Lũy kế | I10: ="Đạt DK: "&COUNTIF(K12:K31,">=0.995") | K10: ="☀️ Đạt: "&COUNTIF(L12:L31,">=0.995") | BA10: ='Tính'!B10 | BB10: ='Tính'!D10 | BC10: =IF($AZ$1=0,'Tính'!$Z$10,CHOOSE($AZ$1,'Tính'!$G$10,'Tính'!$L$10,'Tính'!$Q$10,'Tính'!$V$10)) | BD10: =IF($AZ$1=0,'Tính'!$Y$10,CHOOSE($AZ$1,'Tính'!$E$10,'Tính'!$J$10,'Tính'!$O$10,'Tính'!$T$10)) | BE10: =IF($AZ$1=0,'Tính'!$AB$10,CHOOSE($AZ$1,'Tính'!$I$10,'Tính'!$N$10,'Tính'!$S$10,'Tính'!$X$10)) | BF10: =IF($AZ$1=0,'Tính'!$AA$10,CHOOSE($AZ$1,'Tính'!$H$10,'Tính'!$M$10,'Tính'!$R$10,'Tính'!$W$10)) | BG10: =IF(BC10>0,BD10/NgayQua*SoNgay/BC10,IF(BD10>0,1,0)) | BH10: =IF(CoRTNhom=1,IF(BC10>0,(BD10+BF10)/(NgayQua+1)*SoNgay/BC10,IF(BD10+BF10>0,1,0)),BG10) | BI10: =IF(BA10="",-1,IF(BB10="Chính",1000,0)+BH10+(20-8)/100000) | BJ10: =IF(LARGE($BI$3:$BI$22,8)<0,"",MATCH(LARGE($BI$3:$BI$22,8),$BI$3:$BI$22,0)) | CA10: 8 | CB10: =IF('Tính'!B46="",0,IF(OR($AZ$1=0,'Tính'!D46=$AZ$1),1,0)) | CC10: =IF(CB10=1,'Tính'!L46*1000+'Tính'!M46+1+(45-8)/1000000,-1) | CD10: =IF(LARGE($CC$3:$CC$47,8)<0,"",MATCH(LARGE($CC$3:$CC$47,8),$CC$3:$CC$47,0))
A11: Nhóm hàng | B11: Loại | C11: Target ngày | D11: Thực hiện | E11: Tỉ lệ | G11: Nhóm hàng | H11: Target tháng | I11: Thực hiện | J11: % Hiện tại | K11: DK | L11: ☀️ DK mai | BA11: ='Tính'!B11 | BB11: ='Tính'!D11 | BC11: =IF($AZ$1=0,'Tính'!$Z$11,CHOOSE($AZ$1,'Tính'!$G$11,'Tính'!$L$11,'Tính'!$Q$11,'Tính'!$V$11)) | BD11: =IF($AZ$1=0,'Tính'!$Y$11,CHOOSE($AZ$1,'Tính'!$E$11,'Tính'!$J$11,'Tính'!$O$11,'Tính'!$T$11)) | BE11: =IF($AZ$1=0,'Tính'!$AB$11,CHOOSE($AZ$1,'Tính'!$I$11,'Tính'!$N$11,'Tính'!$S$11,'Tính'!$X$11)) | BF11: =IF($AZ$1=0,'Tính'!$AA$11,CHOOSE($AZ$1,'Tính'!$H$11,'Tính'!$M$11,'Tính'!$R$11,'Tính'!$W$11)) | BG11: =IF(BC11>0,BD11/NgayQua*SoNgay/BC11,IF(BD11>0,1,0)) | BH11: =IF(CoRTNhom=1,IF(BC11>0,(BD11+BF11)/(NgayQua+1)*SoNgay/BC11,IF(BD11+BF11>0,1,0)),BG11) | BI11: =IF(BA11="",-1,IF(BB11="Chính",1000,0)+BH11+(20-9)/100000) | BJ11: =IF(LARGE($BI$3:$BI$22,9)<0,"",MATCH(LARGE($BI$3:$BI$22,9),$BI$3:$BI$22,0)) | CA11: 9 | CB11: =IF('Tính'!B47="",0,IF(OR($AZ$1=0,'Tính'!D47=$AZ$1),1,0)) | CC11: =IF(CB11=1,'Tính'!L47*1000+'Tính'!M47+1+(45-9)/1000000,-1) | CD11: =IF(LARGE($CC$3:$CC$47,9)<0,"",MATCH(LARGE($CC$3:$CC$47,9),$CC$3:$CC$47,0))
A12: =IF($BJ$3="","",INDEX($BA$3:$BA$22,$BJ$3)) | B12: =IF($BJ$3="","",INDEX($BB$3:$BB$22,$BJ$3)) | C12: =IF($BJ$3="","",INDEX($BE$3:$BE$22,$BJ$3)) | D12: =IF($BJ$3="","",INDEX($BF$3:$BF$22,$BJ$3)) | E12: =IF(A12="","",IF(D12=0,"-",IF(C12>0,D12/C12,1))) | G12: =A12 | H12: =IF($BJ$3="","",INDEX($BC$3:$BC$22,$BJ$3)) | I12: =IF($BJ$3="","",INDEX($BD$3:$BD$22,$BJ$3)) | J12: =IF(A12="","",IF(H12>0,I12/H12,1)) | K12: =IF($BJ$3="","",INDEX($BG$3:$BG$22,$BJ$3)) | L12: =IF($BJ$3="","",INDEX($BH$3:$BH$22,$BJ$3)) | BA12: ='Tính'!B12 | BB12: ='Tính'!D12 | BC12: =IF($AZ$1=0,'Tính'!$Z$12,CHOOSE($AZ$1,'Tính'!$G$12,'Tính'!$L$12,'Tính'!$Q$12,'Tính'!$V$12)) | BD12: =IF($AZ$1=0,'Tính'!$Y$12,CHOOSE($AZ$1,'Tính'!$E$12,'Tính'!$J$12,'Tính'!$O$12,'Tính'!$T$12)) | BE12: =IF($AZ$1=0,'Tính'!$AB$12,CHOOSE($AZ$1,'Tính'!$I$12,'Tính'!$N$12,'Tính'!$S$12,'Tính'!$X$12)) | BF12: =IF($AZ$1=0,'Tính'!$AA$12,CHOOSE($AZ$1,'Tính'!$H$12,'Tính'!$M$12,'Tính'!$R$12,'Tính'!$W$12)) | BG12: =IF(BC12>0,BD12/NgayQua*SoNgay/BC12,IF(BD12>0,1,0)) | BH12: =IF(CoRTNhom=1,IF(BC12>0,(BD12+BF12)/(NgayQua+1)*SoNgay/BC12,IF(BD12+BF12>0,1,0)),BG12) | BI12: =IF(BA12="",-1,IF(BB12="Chính",1000,0)+BH12+(20-10)/100000) | BJ12: =IF(LARGE($BI$3:$BI$22,10)<0,"",MATCH(LARGE($BI$3:$BI$22,10),$BI$3:$BI$22,0)) | CA12: 10 | CB12: =IF('Tính'!B48="",0,IF(OR($AZ$1=0,'Tính'!D48=$AZ$1),1,0)) | CC12: =IF(CB12=1,'Tính'!L48*1000+'Tính'!M48+1+(45-10)/1000000,-1) | CD12: =IF(LARGE($CC$3:$CC$47,10)<0,"",MATCH(LARGE($CC$3:$CC$47,10),$CC$3:$CC$47,0))
A13: =IF($BJ$4="","",INDEX($BA$3:$BA$22,$BJ$4)) | B13: =IF($BJ$4="","",INDEX($BB$3:$BB$22,$BJ$4)) | C13: =IF($BJ$4="","",INDEX($BE$3:$BE$22,$BJ$4)) | D13: =IF($BJ$4="","",INDEX($BF$3:$BF$22,$BJ$4)) | E13: =IF(A13="","",IF(D13=0,"-",IF(C13>0,D13/C13,1))) | G13: =A13 | H13: =IF($BJ$4="","",INDEX($BC$3:$BC$22,$BJ$4)) | I13: =IF($BJ$4="","",INDEX($BD$3:$BD$22,$BJ$4)) | J13: =IF(A13="","",IF(H13>0,I13/H13,1)) | K13: =IF($BJ$4="","",INDEX($BG$3:$BG$22,$BJ$4)) | L13: =IF($BJ$4="","",INDEX($BH$3:$BH$22,$BJ$4)) | BA13: ='Tính'!B13 | BB13: ='Tính'!D13 | BC13: =IF($AZ$1=0,'Tính'!$Z$13,CHOOSE($AZ$1,'Tính'!$G$13,'Tính'!$L$13,'Tính'!$Q$13,'Tính'!$V$13)) | BD13: =IF($AZ$1=0,'Tính'!$Y$13,CHOOSE($AZ$1,'Tính'!$E$13,'Tính'!$J$13,'Tính'!$O$13,'Tính'!$T$13)) | BE13: =IF($AZ$1=0,'Tính'!$AB$13,CHOOSE($AZ$1,'Tính'!$I$13,'Tính'!$N$13,'Tính'!$S$13,'Tính'!$X$13)) | BF13: =IF($AZ$1=0,'Tính'!$AA$13,CHOOSE($AZ$1,'Tính'!$H$13,'Tính'!$M$13,'Tính'!$R$13,'Tính'!$W$13)) | BG13: =IF(BC13>0,BD13/NgayQua*SoNgay/BC13,IF(BD13>0,1,0)) | BH13: =IF(CoRTNhom=1,IF(BC13>0,(BD13+BF13)/(NgayQua+1)*SoNgay/BC13,IF(BD13+BF13>0,1,0)),BG13) | BI13: =IF(BA13="",-1,IF(BB13="Chính",1000,0)+BH13+(20-11)/100000) | BJ13: =IF(LARGE($BI$3:$BI$22,11)<0,"",MATCH(LARGE($BI$3:$BI$22,11),$BI$3:$BI$22,0)) | CA13: 11 | CB13: =IF('Tính'!B49="",0,IF(OR($AZ$1=0,'Tính'!D49=$AZ$1),1,0)) | CC13: =IF(CB13=1,'Tính'!L49*1000+'Tính'!M49+1+(45-11)/1000000,-1) | CD13: =IF(LARGE($CC$3:$CC$47,11)<0,"",MATCH(LARGE($CC$3:$CC$47,11),$CC$3:$CC$47,0))
A14: =IF($BJ$5="","",INDEX($BA$3:$BA$22,$BJ$5)) | B14: =IF($BJ$5="","",INDEX($BB$3:$BB$22,$BJ$5)) | C14: =IF($BJ$5="","",INDEX($BE$3:$BE$22,$BJ$5)) | D14: =IF($BJ$5="","",INDEX($BF$3:$BF$22,$BJ$5)) | E14: =IF(A14="","",IF(D14=0,"-",IF(C14>0,D14/C14,1))) | G14: =A14 | H14: =IF($BJ$5="","",INDEX($BC$3:$BC$22,$BJ$5)) | I14: =IF($BJ$5="","",INDEX($BD$3:$BD$22,$BJ$5)) | J14: =IF(A14="","",IF(H14>0,I14/H14,1)) | K14: =IF($BJ$5="","",INDEX($BG$3:$BG$22,$BJ$5)) | L14: =IF($BJ$5="","",INDEX($BH$3:$BH$22,$BJ$5)) | BA14: ='Tính'!B14 | BB14: ='Tính'!D14 | BC14: =IF($AZ$1=0,'Tính'!$Z$14,CHOOSE($AZ$1,'Tính'!$G$14,'Tính'!$L$14,'Tính'!$Q$14,'Tính'!$V$14)) | BD14: =IF($AZ$1=0,'Tính'!$Y$14,CHOOSE($AZ$1,'Tính'!$E$14,'Tính'!$J$14,'Tính'!$O$14,'Tính'!$T$14)) | BE14: =IF($AZ$1=0,'Tính'!$AB$14,CHOOSE($AZ$1,'Tính'!$I$14,'Tính'!$N$14,'Tính'!$S$14,'Tính'!$X$14)) | BF14: =IF($AZ$1=0,'Tính'!$AA$14,CHOOSE($AZ$1,'Tính'!$H$14,'Tính'!$M$14,'Tính'!$R$14,'Tính'!$W$14)) | BG14: =IF(BC14>0,BD14/NgayQua*SoNgay/BC14,IF(BD14>0,1,0)) | BH14: =IF(CoRTNhom=1,IF(BC14>0,(BD14+BF14)/(NgayQua+1)*SoNgay/BC14,IF(BD14+BF14>0,1,0)),BG14) | BI14: =IF(BA14="",-1,IF(BB14="Chính",1000,0)+BH14+(20-12)/100000) | BJ14: =IF(LARGE($BI$3:$BI$22,12)<0,"",MATCH(LARGE($BI$3:$BI$22,12),$BI$3:$BI$22,0)) | CA14: 12 | CB14: =IF('Tính'!B50="",0,IF(OR($AZ$1=0,'Tính'!D50=$AZ$1),1,0)) | CC14: =IF(CB14=1,'Tính'!L50*1000+'Tính'!M50+1+(45-12)/1000000,-1) | CD14: =IF(LARGE($CC$3:$CC$47,12)<0,"",MATCH(LARGE($CC$3:$CC$47,12),$CC$3:$CC$47,0))
A15: =IF($BJ$6="","",INDEX($BA$3:$BA$22,$BJ$6)) | B15: =IF($BJ$6="","",INDEX($BB$3:$BB$22,$BJ$6)) | C15: =IF($BJ$6="","",INDEX($BE$3:$BE$22,$BJ$6)) | D15: =IF($BJ$6="","",INDEX($BF$3:$BF$22,$BJ$6)) | E15: =IF(A15="","",IF(D15=0,"-",IF(C15>0,D15/C15,1))) | G15: =A15 | H15: =IF($BJ$6="","",INDEX($BC$3:$BC$22,$BJ$6)) | I15: =IF($BJ$6="","",INDEX($BD$3:$BD$22,$BJ$6)) | J15: =IF(A15="","",IF(H15>0,I15/H15,1)) | K15: =IF($BJ$6="","",INDEX($BG$3:$BG$22,$BJ$6)) | L15: =IF($BJ$6="","",INDEX($BH$3:$BH$22,$BJ$6)) | BA15: ='Tính'!B15 | BB15: ='Tính'!D15 | BC15: =IF($AZ$1=0,'Tính'!$Z$15,CHOOSE($AZ$1,'Tính'!$G$15,'Tính'!$L$15,'Tính'!$Q$15,'Tính'!$V$15)) | BD15: =IF($AZ$1=0,'Tính'!$Y$15,CHOOSE($AZ$1,'Tính'!$E$15,'Tính'!$J$15,'Tính'!$O$15,'Tính'!$T$15)) | BE15: =IF($AZ$1=0,'Tính'!$AB$15,CHOOSE($AZ$1,'Tính'!$I$15,'Tính'!$N$15,'Tính'!$S$15,'Tính'!$X$15)) | BF15: =IF($AZ$1=0,'Tính'!$AA$15,CHOOSE($AZ$1,'Tính'!$H$15,'Tính'!$M$15,'Tính'!$R$15,'Tính'!$W$15)) | BG15: =IF(BC15>0,BD15/NgayQua*SoNgay/BC15,IF(BD15>0,1,0)) | BH15: =IF(CoRTNhom=1,IF(BC15>0,(BD15+BF15)/(NgayQua+1)*SoNgay/BC15,IF(BD15+BF15>0,1,0)),BG15) | BI15: =IF(BA15="",-1,IF(BB15="Chính",1000,0)+BH15+(20-13)/100000) | BJ15: =IF(LARGE($BI$3:$BI$22,13)<0,"",MATCH(LARGE($BI$3:$BI$22,13),$BI$3:$BI$22,0)) | CA15: 13 | CB15: =IF('Tính'!B51="",0,IF(OR($AZ$1=0,'Tính'!D51=$AZ$1),1,0)) | CC15: =IF(CB15=1,'Tính'!L51*1000+'Tính'!M51+1+(45-13)/1000000,-1) | CD15: =IF(LARGE($CC$3:$CC$47,13)<0,"",MATCH(LARGE($CC$3:$CC$47,13),$CC$3:$CC$47,0))
A16: =IF($BJ$7="","",INDEX($BA$3:$BA$22,$BJ$7)) | B16: =IF($BJ$7="","",INDEX($BB$3:$BB$22,$BJ$7)) | C16: =IF($BJ$7="","",INDEX($BE$3:$BE$22,$BJ$7)) | D16: =IF($BJ$7="","",INDEX($BF$3:$BF$22,$BJ$7)) | E16: =IF(A16="","",IF(D16=0,"-",IF(C16>0,D16/C16,1))) | G16: =A16 | H16: =IF($BJ$7="","",INDEX($BC$3:$BC$22,$BJ$7)) | I16: =IF($BJ$7="","",INDEX($BD$3:$BD$22,$BJ$7)) | J16: =IF(A16="","",IF(H16>0,I16/H16,1)) | K16: =IF($BJ$7="","",INDEX($BG$3:$BG$22,$BJ$7)) | L16: =IF($BJ$7="","",INDEX($BH$3:$BH$22,$BJ$7)) | BA16: ='Tính'!B16 | BB16: ='Tính'!D16 | BC16: =IF($AZ$1=0,'Tính'!$Z$16,CHOOSE($AZ$1,'Tính'!$G$16,'Tính'!$L$16,'Tính'!$Q$16,'Tính'!$V$16)) | BD16: =IF($AZ$1=0,'Tính'!$Y$16,CHOOSE($AZ$1,'Tính'!$E$16,'Tính'!$J$16,'Tính'!$O$16,'Tính'!$T$16)) | BE16: =IF($AZ$1=0,'Tính'!$AB$16,CHOOSE($AZ$1,'Tính'!$I$16,'Tính'!$N$16,'Tính'!$S$16,'Tính'!$X$16)) | BF16: =IF($AZ$1=0,'Tính'!$AA$16,CHOOSE($AZ$1,'Tính'!$H$16,'Tính'!$M$16,'Tính'!$R$16,'Tính'!$W$16)) | BG16: =IF(BC16>0,BD16/NgayQua*SoNgay/BC16,IF(BD16>0,1,0)) | BH16: =IF(CoRTNhom=1,IF(BC16>0,(BD16+BF16)/(NgayQua+1)*SoNgay/BC16,IF(BD16+BF16>0,1,0)),BG16) | BI16: =IF(BA16="",-1,IF(BB16="Chính",1000,0)+BH16+(20-14)/100000) | BJ16: =IF(LARGE($BI$3:$BI$22,14)<0,"",MATCH(LARGE($BI$3:$BI$22,14),$BI$3:$BI$22,0)) | CA16: 14 | CB16: =IF('Tính'!B52="",0,IF(OR($AZ$1=0,'Tính'!D52=$AZ$1),1,0)) | CC16: =IF(CB16=1,'Tính'!L52*1000+'Tính'!M52+1+(45-14)/1000000,-1) | CD16: =IF(LARGE($CC$3:$CC$47,14)<0,"",MATCH(LARGE($CC$3:$CC$47,14),$CC$3:$CC$47,0))
A17: =IF($BJ$8="","",INDEX($BA$3:$BA$22,$BJ$8)) | B17: =IF($BJ$8="","",INDEX($BB$3:$BB$22,$BJ$8)) | C17: =IF($BJ$8="","",INDEX($BE$3:$BE$22,$BJ$8)) | D17: =IF($BJ$8="","",INDEX($BF$3:$BF$22,$BJ$8)) | E17: =IF(A17="","",IF(D17=0,"-",IF(C17>0,D17/C17,1))) | G17: =A17 | H17: =IF($BJ$8="","",INDEX($BC$3:$BC$22,$BJ$8)) | I17: =IF($BJ$8="","",INDEX($BD$3:$BD$22,$BJ$8)) | J17: =IF(A17="","",IF(H17>0,I17/H17,1)) | K17: =IF($BJ$8="","",INDEX($BG$3:$BG$22,$BJ$8)) | L17: =IF($BJ$8="","",INDEX($BH$3:$BH$22,$BJ$8)) | BA17: ='Tính'!B17 | BB17: ='Tính'!D17 | BC17: =IF($AZ$1=0,'Tính'!$Z$17,CHOOSE($AZ$1,'Tính'!$G$17,'Tính'!$L$17,'Tính'!$Q$17,'Tính'!$V$17)) | BD17: =IF($AZ$1=0,'Tính'!$Y$17,CHOOSE($AZ$1,'Tính'!$E$17,'Tính'!$J$17,'Tính'!$O$17,'Tính'!$T$17)) | BE17: =IF($AZ$1=0,'Tính'!$AB$17,CHOOSE($AZ$1,'Tính'!$I$17,'Tính'!$N$17,'Tính'!$S$17,'Tính'!$X$17)) | BF17: =IF($AZ$1=0,'Tính'!$AA$17,CHOOSE($AZ$1,'Tính'!$H$17,'Tính'!$M$17,'Tính'!$R$17,'Tính'!$W$17)) | BG17: =IF(BC17>0,BD17/NgayQua*SoNgay/BC17,IF(BD17>0,1,0)) | BH17: =IF(CoRTNhom=1,IF(BC17>0,(BD17+BF17)/(NgayQua+1)*SoNgay/BC17,IF(BD17+BF17>0,1,0)),BG17) | BI17: =IF(BA17="",-1,IF(BB17="Chính",1000,0)+BH17+(20-15)/100000) | BJ17: =IF(LARGE($BI$3:$BI$22,15)<0,"",MATCH(LARGE($BI$3:$BI$22,15),$BI$3:$BI$22,0)) | CA17: 15 | CB17: =IF('Tính'!B53="",0,IF(OR($AZ$1=0,'Tính'!D53=$AZ$1),1,0)) | CC17: =IF(CB17=1,'Tính'!L53*1000+'Tính'!M53+1+(45-15)/1000000,-1) | CD17: =IF(LARGE($CC$3:$CC$47,15)<0,"",MATCH(LARGE($CC$3:$CC$47,15),$CC$3:$CC$47,0))
A18: =IF($BJ$9="","",INDEX($BA$3:$BA$22,$BJ$9)) | B18: =IF($BJ$9="","",INDEX($BB$3:$BB$22,$BJ$9)) | C18: =IF($BJ$9="","",INDEX($BE$3:$BE$22,$BJ$9)) | D18: =IF($BJ$9="","",INDEX($BF$3:$BF$22,$BJ$9)) | E18: =IF(A18="","",IF(D18=0,"-",IF(C18>0,D18/C18,1))) | G18: =A18 | H18: =IF($BJ$9="","",INDEX($BC$3:$BC$22,$BJ$9)) | I18: =IF($BJ$9="","",INDEX($BD$3:$BD$22,$BJ$9)) | J18: =IF(A18="","",IF(H18>0,I18/H18,1)) | K18: =IF($BJ$9="","",INDEX($BG$3:$BG$22,$BJ$9)) | L18: =IF($BJ$9="","",INDEX($BH$3:$BH$22,$BJ$9)) | BA18: ='Tính'!B18 | BB18: ='Tính'!D18 | BC18: =IF($AZ$1=0,'Tính'!$Z$18,CHOOSE($AZ$1,'Tính'!$G$18,'Tính'!$L$18,'Tính'!$Q$18,'Tính'!$V$18)) | BD18: =IF($AZ$1=0,'Tính'!$Y$18,CHOOSE($AZ$1,'Tính'!$E$18,'Tính'!$J$18,'Tính'!$O$18,'Tính'!$T$18)) | BE18: =IF($AZ$1=0,'Tính'!$AB$18,CHOOSE($AZ$1,'Tính'!$I$18,'Tính'!$N$18,'Tính'!$S$18,'Tính'!$X$18)) | BF18: =IF($AZ$1=0,'Tính'!$AA$18,CHOOSE($AZ$1,'Tính'!$H$18,'Tính'!$M$18,'Tính'!$R$18,'Tính'!$W$18)) | BG18: =IF(BC18>0,BD18/NgayQua*SoNgay/BC18,IF(BD18>0,1,0)) | BH18: =IF(CoRTNhom=1,IF(BC18>0,(BD18+BF18)/(NgayQua+1)*SoNgay/BC18,IF(BD18+BF18>0,1,0)),BG18) | BI18: =IF(BA18="",-1,IF(BB18="Chính",1000,0)+BH18+(20-16)/100000) | BJ18: =IF(LARGE($BI$3:$BI$22,16)<0,"",MATCH(LARGE($BI$3:$BI$22,16),$BI$3:$BI$22,0)) | CA18: 16 | CB18: =IF('Tính'!B54="",0,IF(OR($AZ$1=0,'Tính'!D54=$AZ$1),1,0)) | CC18: =IF(CB18=1,'Tính'!L54*1000+'Tính'!M54+1+(45-16)/1000000,-1) | CD18: =IF(LARGE($CC$3:$CC$47,16)<0,"",MATCH(LARGE($CC$3:$CC$47,16),$CC$3:$CC$47,0))
A19: =IF($BJ$10="","",INDEX($BA$3:$BA$22,$BJ$10)) | B19: =IF($BJ$10="","",INDEX($BB$3:$BB$22,$BJ$10)) | C19: =IF($BJ$10="","",INDEX($BE$3:$BE$22,$BJ$10)) | D19: =IF($BJ$10="","",INDEX($BF$3:$BF$22,$BJ$10)) | E19: =IF(A19="","",IF(D19=0,"-",IF(C19>0,D19/C19,1))) | G19: =A19 | H19: =IF($BJ$10="","",INDEX($BC$3:$BC$22,$BJ$10)) | I19: =IF($BJ$10="","",INDEX($BD$3:$BD$22,$BJ$10)) | J19: =IF(A19="","",IF(H19>0,I19/H19,1)) | K19: =IF($BJ$10="","",INDEX($BG$3:$BG$22,$BJ$10)) | L19: =IF($BJ$10="","",INDEX($BH$3:$BH$22,$BJ$10)) | BA19: ='Tính'!B19 | BB19: ='Tính'!D19 | BC19: =IF($AZ$1=0,'Tính'!$Z$19,CHOOSE($AZ$1,'Tính'!$G$19,'Tính'!$L$19,'Tính'!$Q$19,'Tính'!$V$19)) | BD19: =IF($AZ$1=0,'Tính'!$Y$19,CHOOSE($AZ$1,'Tính'!$E$19,'Tính'!$J$19,'Tính'!$O$19,'Tính'!$T$19)) | BE19: =IF($AZ$1=0,'Tính'!$AB$19,CHOOSE($AZ$1,'Tính'!$I$19,'Tính'!$N$19,'Tính'!$S$19,'Tính'!$X$19)) | BF19: =IF($AZ$1=0,'Tính'!$AA$19,CHOOSE($AZ$1,'Tính'!$H$19,'Tính'!$M$19,'Tính'!$R$19,'Tính'!$W$19)) | BG19: =IF(BC19>0,BD19/NgayQua*SoNgay/BC19,IF(BD19>0,1,0)) | BH19: =IF(CoRTNhom=1,IF(BC19>0,(BD19+BF19)/(NgayQua+1)*SoNgay/BC19,IF(BD19+BF19>0,1,0)),BG19) | BI19: =IF(BA19="",-1,IF(BB19="Chính",1000,0)+BH19+(20-17)/100000) | BJ19: =IF(LARGE($BI$3:$BI$22,17)<0,"",MATCH(LARGE($BI$3:$BI$22,17),$BI$3:$BI$22,0)) | CA19: 17 | CB19: =IF('Tính'!B55="",0,IF(OR($AZ$1=0,'Tính'!D55=$AZ$1),1,0)) | CC19: =IF(CB19=1,'Tính'!L55*1000+'Tính'!M55+1+(45-17)/1000000,-1) | CD19: =IF(LARGE($CC$3:$CC$47,17)<0,"",MATCH(LARGE($CC$3:$CC$47,17),$CC$3:$CC$47,0))
A20: =IF($BJ$11="","",INDEX($BA$3:$BA$22,$BJ$11)) | B20: =IF($BJ$11="","",INDEX($BB$3:$BB$22,$BJ$11)) | C20: =IF($BJ$11="","",INDEX($BE$3:$BE$22,$BJ$11)) | D20: =IF($BJ$11="","",INDEX($BF$3:$BF$22,$BJ$11)) | E20: =IF(A20="","",IF(D20=0,"-",IF(C20>0,D20/C20,1))) | G20: =A20 | H20: =IF($BJ$11="","",INDEX($BC$3:$BC$22,$BJ$11)) | I20: =IF($BJ$11="","",INDEX($BD$3:$BD$22,$BJ$11)) | J20: =IF(A20="","",IF(H20>0,I20/H20,1)) | K20: =IF($BJ$11="","",INDEX($BG$3:$BG$22,$BJ$11)) | L20: =IF($BJ$11="","",INDEX($BH$3:$BH$22,$BJ$11)) | BA20: ='Tính'!B20 | BB20: ='Tính'!D20 | BC20: =IF($AZ$1=0,'Tính'!$Z$20,CHOOSE($AZ$1,'Tính'!$G$20,'Tính'!$L$20,'Tính'!$Q$20,'Tính'!$V$20)) | BD20: =IF($AZ$1=0,'Tính'!$Y$20,CHOOSE($AZ$1,'Tính'!$E$20,'Tính'!$J$20,'Tính'!$O$20,'Tính'!$T$20)) | BE20: =IF($AZ$1=0,'Tính'!$AB$20,CHOOSE($AZ$1,'Tính'!$I$20,'Tính'!$N$20,'Tính'!$S$20,'Tính'!$X$20)) | BF20: =IF($AZ$1=0,'Tính'!$AA$20,CHOOSE($AZ$1,'Tính'!$H$20,'Tính'!$M$20,'Tính'!$R$20,'Tính'!$W$20)) | BG20: =IF(BC20>0,BD20/NgayQua*SoNgay/BC20,IF(BD20>0,1,0)) | BH20: =IF(CoRTNhom=1,IF(BC20>0,(BD20+BF20)/(NgayQua+1)*SoNgay/BC20,IF(BD20+BF20>0,1,0)),BG20) | BI20: =IF(BA20="",-1,IF(BB20="Chính",1000,0)+BH20+(20-18)/100000) | BJ20: =IF(LARGE($BI$3:$BI$22,18)<0,"",MATCH(LARGE($BI$3:$BI$22,18),$BI$3:$BI$22,0)) | CA20: 18 | CB20: =IF('Tính'!B56="",0,IF(OR($AZ$1=0,'Tính'!D56=$AZ$1),1,0)) | CC20: =IF(CB20=1,'Tính'!L56*1000+'Tính'!M56+1+(45-18)/1000000,-1) | CD20: =IF(LARGE($CC$3:$CC$47,18)<0,"",MATCH(LARGE($CC$3:$CC$47,18),$CC$3:$CC$47,0))
A21: =IF($BJ$12="","",INDEX($BA$3:$BA$22,$BJ$12)) | B21: =IF($BJ$12="","",INDEX($BB$3:$BB$22,$BJ$12)) | C21: =IF($BJ$12="","",INDEX($BE$3:$BE$22,$BJ$12)) | D21: =IF($BJ$12="","",INDEX($BF$3:$BF$22,$BJ$12)) | E21: =IF(A21="","",IF(D21=0,"-",IF(C21>0,D21/C21,1))) | G21: =A21 | H21: =IF($BJ$12="","",INDEX($BC$3:$BC$22,$BJ$12)) | I21: =IF($BJ$12="","",INDEX($BD$3:$BD$22,$BJ$12)) | J21: =IF(A21="","",IF(H21>0,I21/H21,1)) | K21: =IF($BJ$12="","",INDEX($BG$3:$BG$22,$BJ$12)) | L21: =IF($BJ$12="","",INDEX($BH$3:$BH$22,$BJ$12)) | BA21: ='Tính'!B21 | BB21: ='Tính'!D21 | BC21: =IF($AZ$1=0,'Tính'!$Z$21,CHOOSE($AZ$1,'Tính'!$G$21,'Tính'!$L$21,'Tính'!$Q$21,'Tính'!$V$21)) | BD21: =IF($AZ$1=0,'Tính'!$Y$21,CHOOSE($AZ$1,'Tính'!$E$21,'Tính'!$J$21,'Tính'!$O$21,'Tính'!$T$21)) | BE21: =IF($AZ$1=0,'Tính'!$AB$21,CHOOSE($AZ$1,'Tính'!$I$21,'Tính'!$N$21,'Tính'!$S$21,'Tính'!$X$21)) | BF21: =IF($AZ$1=0,'Tính'!$AA$21,CHOOSE($AZ$1,'Tính'!$H$21,'Tính'!$M$21,'Tính'!$R$21,'Tính'!$W$21)) | BG21: =IF(BC21>0,BD21/NgayQua*SoNgay/BC21,IF(BD21>0,1,0)) | BH21: =IF(CoRTNhom=1,IF(BC21>0,(BD21+BF21)/(NgayQua+1)*SoNgay/BC21,IF(BD21+BF21>0,1,0)),BG21) | BI21: =IF(BA21="",-1,IF(BB21="Chính",1000,0)+BH21+(20-19)/100000) | BJ21: =IF(LARGE($BI$3:$BI$22,19)<0,"",MATCH(LARGE($BI$3:$BI$22,19),$BI$3:$BI$22,0)) | CA21: 19 | CB21: =IF('Tính'!B57="",0,IF(OR($AZ$1=0,'Tính'!D57=$AZ$1),1,0)) | CC21: =IF(CB21=1,'Tính'!L57*1000+'Tính'!M57+1+(45-19)/1000000,-1) | CD21: =IF(LARGE($CC$3:$CC$47,19)<0,"",MATCH(LARGE($CC$3:$CC$47,19),$CC$3:$CC$47,0))
A22: =IF($BJ$13="","",INDEX($BA$3:$BA$22,$BJ$13)) | B22: =IF($BJ$13="","",INDEX($BB$3:$BB$22,$BJ$13)) | C22: =IF($BJ$13="","",INDEX($BE$3:$BE$22,$BJ$13)) | D22: =IF($BJ$13="","",INDEX($BF$3:$BF$22,$BJ$13)) | E22: =IF(A22="","",IF(D22=0,"-",IF(C22>0,D22/C22,1))) | G22: =A22 | H22: =IF($BJ$13="","",INDEX($BC$3:$BC$22,$BJ$13)) | I22: =IF($BJ$13="","",INDEX($BD$3:$BD$22,$BJ$13)) | J22: =IF(A22="","",IF(H22>0,I22/H22,1)) | K22: =IF($BJ$13="","",INDEX($BG$3:$BG$22,$BJ$13)) | L22: =IF($BJ$13="","",INDEX($BH$3:$BH$22,$BJ$13)) | BA22: ='Tính'!B22 | BB22: ='Tính'!D22 | BC22: =IF($AZ$1=0,'Tính'!$Z$22,CHOOSE($AZ$1,'Tính'!$G$22,'Tính'!$L$22,'Tính'!$Q$22,'Tính'!$V$22)) | BD22: =IF($AZ$1=0,'Tính'!$Y$22,CHOOSE($AZ$1,'Tính'!$E$22,'Tính'!$J$22,'Tính'!$O$22,'Tính'!$T$22)) | BE22: =IF($AZ$1=0,'Tính'!$AB$22,CHOOSE($AZ$1,'Tính'!$I$22,'Tính'!$N$22,'Tính'!$S$22,'Tính'!$X$22)) | BF22: =IF($AZ$1=0,'Tính'!$AA$22,CHOOSE($AZ$1,'Tính'!$H$22,'Tính'!$M$22,'Tính'!$R$22,'Tính'!$W$22)) | BG22: =IF(BC22>0,BD22/NgayQua*SoNgay/BC22,IF(BD22>0,1,0)) | BH22: =IF(CoRTNhom=1,IF(BC22>0,(BD22+BF22)/(NgayQua+1)*SoNgay/BC22,IF(BD22+BF22>0,1,0)),BG22) | BI22: =IF(BA22="",-1,IF(BB22="Chính",1000,0)+BH22+(20-20)/100000) | BJ22: =IF(LARGE($BI$3:$BI$22,20)<0,"",MATCH(LARGE($BI$3:$BI$22,20),$BI$3:$BI$22,0)) | CA22: 20 | CB22: =IF('Tính'!B58="",0,IF(OR($AZ$1=0,'Tính'!D58=$AZ$1),1,0)) | CC22: =IF(CB22=1,'Tính'!L58*1000+'Tính'!M58+1+(45-20)/1000000,-1) | CD22: =IF(LARGE($CC$3:$CC$47,20)<0,"",MATCH(LARGE($CC$3:$CC$47,20),$CC$3:$CC$47,0))
A23: =IF($BJ$14="","",INDEX($BA$3:$BA$22,$BJ$14)) | B23: =IF($BJ$14="","",INDEX($BB$3:$BB$22,$BJ$14)) | C23: =IF($BJ$14="","",INDEX($BE$3:$BE$22,$BJ$14)) | D23: =IF($BJ$14="","",INDEX($BF$3:$BF$22,$BJ$14)) | E23: =IF(A23="","",IF(D23=0,"-",IF(C23>0,D23/C23,1))) | G23: =A23 | H23: =IF($BJ$14="","",INDEX($BC$3:$BC$22,$BJ$14)) | I23: =IF($BJ$14="","",INDEX($BD$3:$BD$22,$BJ$14)) | J23: =IF(A23="","",IF(H23>0,I23/H23,1)) | K23: =IF($BJ$14="","",INDEX($BG$3:$BG$22,$BJ$14)) | L23: =IF($BJ$14="","",INDEX($BH$3:$BH$22,$BJ$14)) | CA23: 21 | CB23: =IF('Tính'!B59="",0,IF(OR($AZ$1=0,'Tính'!D59=$AZ$1),1,0)) | CC23: =IF(CB23=1,'Tính'!L59*1000+'Tính'!M59+1+(45-21)/1000000,-1) | CD23: =IF(LARGE($CC$3:$CC$47,21)<0,"",MATCH(LARGE($CC$3:$CC$47,21),$CC$3:$CC$47,0))
A24: =IF($BJ$15="","",INDEX($BA$3:$BA$22,$BJ$15)) | B24: =IF($BJ$15="","",INDEX($BB$3:$BB$22,$BJ$15)) | C24: =IF($BJ$15="","",INDEX($BE$3:$BE$22,$BJ$15)) | D24: =IF($BJ$15="","",INDEX($BF$3:$BF$22,$BJ$15)) | E24: =IF(A24="","",IF(D24=0,"-",IF(C24>0,D24/C24,1))) | G24: =A24 | H24: =IF($BJ$15="","",INDEX($BC$3:$BC$22,$BJ$15)) | I24: =IF($BJ$15="","",INDEX($BD$3:$BD$22,$BJ$15)) | J24: =IF(A24="","",IF(H24>0,I24/H24,1)) | K24: =IF($BJ$15="","",INDEX($BG$3:$BG$22,$BJ$15)) | L24: =IF($BJ$15="","",INDEX($BH$3:$BH$22,$BJ$15)) | CA24: 22 | CB24: =IF('Tính'!B60="",0,IF(OR($AZ$1=0,'Tính'!D60=$AZ$1),1,0)) | CC24: =IF(CB24=1,'Tính'!L60*1000+'Tính'!M60+1+(45-22)/1000000,-1) | CD24: =IF(LARGE($CC$3:$CC$47,22)<0,"",MATCH(LARGE($CC$3:$CC$47,22),$CC$3:$CC$47,0))
A25: =IF($BJ$16="","",INDEX($BA$3:$BA$22,$BJ$16)) | B25: =IF($BJ$16="","",INDEX($BB$3:$BB$22,$BJ$16)) | C25: =IF($BJ$16="","",INDEX($BE$3:$BE$22,$BJ$16)) | D25: =IF($BJ$16="","",INDEX($BF$3:$BF$22,$BJ$16)) | E25: =IF(A25="","",IF(D25=0,"-",IF(C25>0,D25/C25,1))) | G25: =A25 | H25: =IF($BJ$16="","",INDEX($BC$3:$BC$22,$BJ$16)) | I25: =IF($BJ$16="","",INDEX($BD$3:$BD$22,$BJ$16)) | J25: =IF(A25="","",IF(H25>0,I25/H25,1)) | K25: =IF($BJ$16="","",INDEX($BG$3:$BG$22,$BJ$16)) | L25: =IF($BJ$16="","",INDEX($BH$3:$BH$22,$BJ$16)) | CA25: 23 | CB25: =IF('Tính'!B61="",0,IF(OR($AZ$1=0,'Tính'!D61=$AZ$1),1,0)) | CC25: =IF(CB25=1,'Tính'!L61*1000+'Tính'!M61+1+(45-23)/1000000,-1) | CD25: =IF(LARGE($CC$3:$CC$47,23)<0,"",MATCH(LARGE($CC$3:$CC$47,23),$CC$3:$CC$47,0))
A26: =IF($BJ$17="","",INDEX($BA$3:$BA$22,$BJ$17)) | B26: =IF($BJ$17="","",INDEX($BB$3:$BB$22,$BJ$17)) | C26: =IF($BJ$17="","",INDEX($BE$3:$BE$22,$BJ$17)) | D26: =IF($BJ$17="","",INDEX($BF$3:$BF$22,$BJ$17)) | E26: =IF(A26="","",IF(D26=0,"-",IF(C26>0,D26/C26,1))) | G26: =A26 | H26: =IF($BJ$17="","",INDEX($BC$3:$BC$22,$BJ$17)) | I26: =IF($BJ$17="","",INDEX($BD$3:$BD$22,$BJ$17)) | J26: =IF(A26="","",IF(H26>0,I26/H26,1)) | K26: =IF($BJ$17="","",INDEX($BG$3:$BG$22,$BJ$17)) | L26: =IF($BJ$17="","",INDEX($BH$3:$BH$22,$BJ$17)) | CA26: 24 | CB26: =IF('Tính'!B62="",0,IF(OR($AZ$1=0,'Tính'!D62=$AZ$1),1,0)) | CC26: =IF(CB26=1,'Tính'!L62*1000+'Tính'!M62+1+(45-24)/1000000,-1) | CD26: =IF(LARGE($CC$3:$CC$47,24)<0,"",MATCH(LARGE($CC$3:$CC$47,24),$CC$3:$CC$47,0))
A27: =IF($BJ$18="","",INDEX($BA$3:$BA$22,$BJ$18)) | B27: =IF($BJ$18="","",INDEX($BB$3:$BB$22,$BJ$18)) | C27: =IF($BJ$18="","",INDEX($BE$3:$BE$22,$BJ$18)) | D27: =IF($BJ$18="","",INDEX($BF$3:$BF$22,$BJ$18)) | E27: =IF(A27="","",IF(D27=0,"-",IF(C27>0,D27/C27,1))) | G27: =A27 | H27: =IF($BJ$18="","",INDEX($BC$3:$BC$22,$BJ$18)) | I27: =IF($BJ$18="","",INDEX($BD$3:$BD$22,$BJ$18)) | J27: =IF(A27="","",IF(H27>0,I27/H27,1)) | K27: =IF($BJ$18="","",INDEX($BG$3:$BG$22,$BJ$18)) | L27: =IF($BJ$18="","",INDEX($BH$3:$BH$22,$BJ$18)) | CA27: 25 | CB27: =IF('Tính'!B63="",0,IF(OR($AZ$1=0,'Tính'!D63=$AZ$1),1,0)) | CC27: =IF(CB27=1,'Tính'!L63*1000+'Tính'!M63+1+(45-25)/1000000,-1) | CD27: =IF(LARGE($CC$3:$CC$47,25)<0,"",MATCH(LARGE($CC$3:$CC$47,25),$CC$3:$CC$47,0))
A28: =IF($BJ$19="","",INDEX($BA$3:$BA$22,$BJ$19)) | B28: =IF($BJ$19="","",INDEX($BB$3:$BB$22,$BJ$19)) | C28: =IF($BJ$19="","",INDEX($BE$3:$BE$22,$BJ$19)) | D28: =IF($BJ$19="","",INDEX($BF$3:$BF$22,$BJ$19)) | E28: =IF(A28="","",IF(D28=0,"-",IF(C28>0,D28/C28,1))) | G28: =A28 | H28: =IF($BJ$19="","",INDEX($BC$3:$BC$22,$BJ$19)) | I28: =IF($BJ$19="","",INDEX($BD$3:$BD$22,$BJ$19)) | J28: =IF(A28="","",IF(H28>0,I28/H28,1)) | K28: =IF($BJ$19="","",INDEX($BG$3:$BG$22,$BJ$19)) | L28: =IF($BJ$19="","",INDEX($BH$3:$BH$22,$BJ$19)) | CA28: 26 | CB28: =IF('Tính'!B64="",0,IF(OR($AZ$1=0,'Tính'!D64=$AZ$1),1,0)) | CC28: =IF(CB28=1,'Tính'!L64*1000+'Tính'!M64+1+(45-26)/1000000,-1) | CD28: =IF(LARGE($CC$3:$CC$47,26)<0,"",MATCH(LARGE($CC$3:$CC$47,26),$CC$3:$CC$47,0))
A29: =IF($BJ$20="","",INDEX($BA$3:$BA$22,$BJ$20)) | B29: =IF($BJ$20="","",INDEX($BB$3:$BB$22,$BJ$20)) | C29: =IF($BJ$20="","",INDEX($BE$3:$BE$22,$BJ$20)) | D29: =IF($BJ$20="","",INDEX($BF$3:$BF$22,$BJ$20)) | E29: =IF(A29="","",IF(D29=0,"-",IF(C29>0,D29/C29,1))) | G29: =A29 | H29: =IF($BJ$20="","",INDEX($BC$3:$BC$22,$BJ$20)) | I29: =IF($BJ$20="","",INDEX($BD$3:$BD$22,$BJ$20)) | J29: =IF(A29="","",IF(H29>0,I29/H29,1)) | K29: =IF($BJ$20="","",INDEX($BG$3:$BG$22,$BJ$20)) | L29: =IF($BJ$20="","",INDEX($BH$3:$BH$22,$BJ$20)) | CA29: 27 | CB29: =IF('Tính'!B65="",0,IF(OR($AZ$1=0,'Tính'!D65=$AZ$1),1,0)) | CC29: =IF(CB29=1,'Tính'!L65*1000+'Tính'!M65+1+(45-27)/1000000,-1) | CD29: =IF(LARGE($CC$3:$CC$47,27)<0,"",MATCH(LARGE($CC$3:$CC$47,27),$CC$3:$CC$47,0))
A30: =IF($BJ$21="","",INDEX($BA$3:$BA$22,$BJ$21)) | B30: =IF($BJ$21="","",INDEX($BB$3:$BB$22,$BJ$21)) | C30: =IF($BJ$21="","",INDEX($BE$3:$BE$22,$BJ$21)) | D30: =IF($BJ$21="","",INDEX($BF$3:$BF$22,$BJ$21)) | E30: =IF(A30="","",IF(D30=0,"-",IF(C30>0,D30/C30,1))) | G30: =A30 | H30: =IF($BJ$21="","",INDEX($BC$3:$BC$22,$BJ$21)) | I30: =IF($BJ$21="","",INDEX($BD$3:$BD$22,$BJ$21)) | J30: =IF(A30="","",IF(H30>0,I30/H30,1)) | K30: =IF($BJ$21="","",INDEX($BG$3:$BG$22,$BJ$21)) | L30: =IF($BJ$21="","",INDEX($BH$3:$BH$22,$BJ$21)) | CA30: 28 | CB30: =IF('Tính'!B66="",0,IF(OR($AZ$1=0,'Tính'!D66=$AZ$1),1,0)) | CC30: =IF(CB30=1,'Tính'!L66*1000+'Tính'!M66+1+(45-28)/1000000,-1) | CD30: =IF(LARGE($CC$3:$CC$47,28)<0,"",MATCH(LARGE($CC$3:$CC$47,28),$CC$3:$CC$47,0))
A31: =IF($BJ$22="","",INDEX($BA$3:$BA$22,$BJ$22)) | B31: =IF($BJ$22="","",INDEX($BB$3:$BB$22,$BJ$22)) | C31: =IF($BJ$22="","",INDEX($BE$3:$BE$22,$BJ$22)) | D31: =IF($BJ$22="","",INDEX($BF$3:$BF$22,$BJ$22)) | E31: =IF(A31="","",IF(D31=0,"-",IF(C31>0,D31/C31,1))) | G31: =A31 | H31: =IF($BJ$22="","",INDEX($BC$3:$BC$22,$BJ$22)) | I31: =IF($BJ$22="","",INDEX($BD$3:$BD$22,$BJ$22)) | J31: =IF(A31="","",IF(H31>0,I31/H31,1)) | K31: =IF($BJ$22="","",INDEX($BG$3:$BG$22,$BJ$22)) | L31: =IF($BJ$22="","",INDEX($BH$3:$BH$22,$BJ$22)) | CA31: 29 | CB31: =IF('Tính'!B67="",0,IF(OR($AZ$1=0,'Tính'!D67=$AZ$1),1,0)) | CC31: =IF(CB31=1,'Tính'!L67*1000+'Tính'!M67+1+(45-29)/1000000,-1) | CD31: =IF(LARGE($CC$3:$CC$47,29)<0,"",MATCH(LARGE($CC$3:$CC$47,29),$CC$3:$CC$47,0))
CA32: 30 | CB32: =IF('Tính'!B68="",0,IF(OR($AZ$1=0,'Tính'!D68=$AZ$1),1,0)) | CC32: =IF(CB32=1,'Tính'!L68*1000+'Tính'!M68+1+(45-30)/1000000,-1) | CD32: =IF(LARGE($CC$3:$CC$47,30)<0,"",MATCH(LARGE($CC$3:$CC$47,30),$CC$3:$CC$47,0))
A33: DOANH THU NV HÔM NAY | G33: LŨY KẾ THÁNG | CA33: 31 | CB33: =IF('Tính'!B69="",0,IF(OR($AZ$1=0,'Tính'!D69=$AZ$1),1,0)) | CC33: =IF(CB33=1,'Tính'!L69*1000+'Tính'!M69+1+(45-31)/1000000,-1) | CD33: =IF(LARGE($CC$3:$CC$47,31)<0,"",MATCH(LARGE($CC$3:$CC$47,31),$CC$3:$CC$47,0))
A34: Nhân viên | C34: Hôm nay ▼ | G34: Lũy kế | H34: Mục tiêu | I34: % HT | J34: Dự kiến | K34: Shop | CA34: 32 | CB34: =IF('Tính'!B70="",0,IF(OR($AZ$1=0,'Tính'!D70=$AZ$1),1,0)) | CC34: =IF(CB34=1,'Tính'!L70*1000+'Tính'!M70+1+(45-32)/1000000,-1) | CD34: =IF(LARGE($CC$3:$CC$47,32)<0,"",MATCH(LARGE($CC$3:$CC$47,32),$CC$3:$CC$47,0))
A35: =IF($CD$3="","",1&". "&IF($CD$3="","",INDEX('Tính'!$C$39:$C$83,$CD$3))) | C35: =IF($CD$3="","",INDEX('Tính'!$L$39:$L$83,$CD$3)) | G35: =IF($CD$3="","",INDEX('Tính'!$K$39:$K$83,$CD$3)) | H35: =IF($CD$3="","",INDEX('Tính'!$J$39:$J$83,$CD$3)) | I35: =IF($CD$3="","",INDEX('Tính'!$N$39:$N$83,$CD$3)) | J35: =IF($CD$3="","",INDEX('Tính'!$M$39:$M$83,$CD$3)) | K35: =IF($CD$3="","",INDEX('Tính'!$O$39:$O$83,$CD$3)) | CA35: 33 | CB35: =IF('Tính'!B71="",0,IF(OR($AZ$1=0,'Tính'!D71=$AZ$1),1,0)) | CC35: =IF(CB35=1,'Tính'!L71*1000+'Tính'!M71+1+(45-33)/1000000,-1) | CD35: =IF(LARGE($CC$3:$CC$47,33)<0,"",MATCH(LARGE($CC$3:$CC$47,33),$CC$3:$CC$47,0))
A36: =IF($CD$4="","",2&". "&IF($CD$4="","",INDEX('Tính'!$C$39:$C$83,$CD$4))) | C36: =IF($CD$4="","",INDEX('Tính'!$L$39:$L$83,$CD$4)) | G36: =IF($CD$4="","",INDEX('Tính'!$K$39:$K$83,$CD$4)) | H36: =IF($CD$4="","",INDEX('Tính'!$J$39:$J$83,$CD$4)) | I36: =IF($CD$4="","",INDEX('Tính'!$N$39:$N$83,$CD$4)) | J36: =IF($CD$4="","",INDEX('Tính'!$M$39:$M$83,$CD$4)) | K36: =IF($CD$4="","",INDEX('Tính'!$O$39:$O$83,$CD$4)) | CA36: 34 | CB36: =IF('Tính'!B72="",0,IF(OR($AZ$1=0,'Tính'!D72=$AZ$1),1,0)) | CC36: =IF(CB36=1,'Tính'!L72*1000+'Tính'!M72+1+(45-34)/1000000,-1) | CD36: =IF(LARGE($CC$3:$CC$47,34)<0,"",MATCH(LARGE($CC$3:$CC$47,34),$CC$3:$CC$47,0))
A37: =IF($CD$5="","",3&". "&IF($CD$5="","",INDEX('Tính'!$C$39:$C$83,$CD$5))) | C37: =IF($CD$5="","",INDEX('Tính'!$L$39:$L$83,$CD$5)) | G37: =IF($CD$5="","",INDEX('Tính'!$K$39:$K$83,$CD$5)) | H37: =IF($CD$5="","",INDEX('Tính'!$J$39:$J$83,$CD$5)) | I37: =IF($CD$5="","",INDEX('Tính'!$N$39:$N$83,$CD$5)) | J37: =IF($CD$5="","",INDEX('Tính'!$M$39:$M$83,$CD$5)) | K37: =IF($CD$5="","",INDEX('Tính'!$O$39:$O$83,$CD$5)) | CA37: 35 | CB37: =IF('Tính'!B73="",0,IF(OR($AZ$1=0,'Tính'!D73=$AZ$1),1,0)) | CC37: =IF(CB37=1,'Tính'!L73*1000+'Tính'!M73+1+(45-35)/1000000,-1) | CD37: =IF(LARGE($CC$3:$CC$47,35)<0,"",MATCH(LARGE($CC$3:$CC$47,35),$CC$3:$CC$47,0))
A38: =IF($CD$6="","",4&". "&IF($CD$6="","",INDEX('Tính'!$C$39:$C$83,$CD$6))) | C38: =IF($CD$6="","",INDEX('Tính'!$L$39:$L$83,$CD$6)) | G38: =IF($CD$6="","",INDEX('Tính'!$K$39:$K$83,$CD$6)) | H38: =IF($CD$6="","",INDEX('Tính'!$J$39:$J$83,$CD$6)) | I38: =IF($CD$6="","",INDEX('Tính'!$N$39:$N$83,$CD$6)) | J38: =IF($CD$6="","",INDEX('Tính'!$M$39:$M$83,$CD$6)) | K38: =IF($CD$6="","",INDEX('Tính'!$O$39:$O$83,$CD$6)) | CA38: 36 | CB38: =IF('Tính'!B74="",0,IF(OR($AZ$1=0,'Tính'!D74=$AZ$1),1,0)) | CC38: =IF(CB38=1,'Tính'!L74*1000+'Tính'!M74+1+(45-36)/1000000,-1) | CD38: =IF(LARGE($CC$3:$CC$47,36)<0,"",MATCH(LARGE($CC$3:$CC$47,36),$CC$3:$CC$47,0))
A39: =IF($CD$7="","",5&". "&IF($CD$7="","",INDEX('Tính'!$C$39:$C$83,$CD$7))) | C39: =IF($CD$7="","",INDEX('Tính'!$L$39:$L$83,$CD$7)) | G39: =IF($CD$7="","",INDEX('Tính'!$K$39:$K$83,$CD$7)) | H39: =IF($CD$7="","",INDEX('Tính'!$J$39:$J$83,$CD$7)) | I39: =IF($CD$7="","",INDEX('Tính'!$N$39:$N$83,$CD$7)) | J39: =IF($CD$7="","",INDEX('Tính'!$M$39:$M$83,$CD$7)) | K39: =IF($CD$7="","",INDEX('Tính'!$O$39:$O$83,$CD$7)) | CA39: 37 | CB39: =IF('Tính'!B75="",0,IF(OR($AZ$1=0,'Tính'!D75=$AZ$1),1,0)) | CC39: =IF(CB39=1,'Tính'!L75*1000+'Tính'!M75+1+(45-37)/1000000,-1) | CD39: =IF(LARGE($CC$3:$CC$47,37)<0,"",MATCH(LARGE($CC$3:$CC$47,37),$CC$3:$CC$47,0))
A40: =IF($CD$8="","",6&". "&IF($CD$8="","",INDEX('Tính'!$C$39:$C$83,$CD$8))) | C40: =IF($CD$8="","",INDEX('Tính'!$L$39:$L$83,$CD$8)) | G40: =IF($CD$8="","",INDEX('Tính'!$K$39:$K$83,$CD$8)) | H40: =IF($CD$8="","",INDEX('Tính'!$J$39:$J$83,$CD$8)) | I40: =IF($CD$8="","",INDEX('Tính'!$N$39:$N$83,$CD$8)) | J40: =IF($CD$8="","",INDEX('Tính'!$M$39:$M$83,$CD$8)) | K40: =IF($CD$8="","",INDEX('Tính'!$O$39:$O$83,$CD$8)) | CA40: 38 | CB40: =IF('Tính'!B76="",0,IF(OR($AZ$1=0,'Tính'!D76=$AZ$1),1,0)) | CC40: =IF(CB40=1,'Tính'!L76*1000+'Tính'!M76+1+(45-38)/1000000,-1) | CD40: =IF(LARGE($CC$3:$CC$47,38)<0,"",MATCH(LARGE($CC$3:$CC$47,38),$CC$3:$CC$47,0))
...

Sheet Lũy kế
A1: ="BÁO CÁO LŨY KẾ — "&'Khai báo'!B3&" · số đến hết "&TEXT(NgayQua,"00")&"/"&'Khai báo'!B4 | AZ1: =IFERROR(MATCH($B$2,'Tính'!$B$31:$B$34,0),0)
A2: Xem: | B2: Tổng cụm | F2: ◀ bấm ô vàng để chọn Tổng cụm hoặc từng siêu thị | BA2: Nhóm (view) | BJ2: Thứ tự
BA3: ='Tính'!B3 | BB3: ='Tính'!D3 | BC3: =IF($AZ$1=0,'Tính'!$Z$3,CHOOSE($AZ$1,'Tính'!$G$3,'Tính'!$L$3,'Tính'!$Q$3,'Tính'!$V$3)) | BD3: =IF($AZ$1=0,'Tính'!$Y$3,CHOOSE($AZ$1,'Tính'!$E$3,'Tính'!$J$3,'Tính'!$O$3,'Tính'!$T$3)) | BE3: =IF($AZ$1=0,'Tính'!$AB$3,CHOOSE($AZ$1,'Tính'!$I$3,'Tính'!$N$3,'Tính'!$S$3,'Tính'!$X$3)) | BF3: =IF($AZ$1=0,'Tính'!$AA$3,CHOOSE($AZ$1,'Tính'!$H$3,'Tính'!$M$3,'Tính'!$R$3,'Tính'!$W$3)) | BG3: =IF(BC3>0,BD3/NgayQua*SoNgay/BC3,IF(BD3>0,1,0)) | BH3: =IF(CoRTNhom=1,IF(BC3>0,(BD3+BF3)/(NgayQua+1)*SoNgay/BC3,IF(BD3+BF3>0,1,0)),BG3) | BI3: =IF(BA3="",-1,IF(BB3="Chính",1000,0)+BG3+(20-1)/100000) | BJ3: =IF(LARGE($BI$3:$BI$22,1)<0,"",MATCH(LARGE($BI$3:$BI$22,1),$BI$3:$BI$22,0)) | CA3: 1 | CB3: =IF('Tính'!B39="",0,IF(OR($AZ$1=0,'Tính'!D39=$AZ$1),1,0)) | CC3: =IF(CB3=1,'Tính'!M39+1+(45-1)/1000000,-1) | CD3: =IF(LARGE($CC$3:$CC$47,1)<0,"",MATCH(LARGE($CC$3:$CC$47,1),$CC$3:$CC$47,0))
A4: Nhóm hàng | B4: =$B$2 | H4: Hạng | I4: Nhân viên | J4: Mục tiêu | K4: DT QĐ | L4: % HT | M4: Dự kiến | N4: NH đạt | BA4: ='Tính'!B4 | BB4: ='Tính'!D4 | BC4: =IF($AZ$1=0,'Tính'!$Z$4,CHOOSE($AZ$1,'Tính'!$G$4,'Tính'!$L$4,'Tính'!$Q$4,'Tính'!$V$4)) | BD4: =IF($AZ$1=0,'Tính'!$Y$4,CHOOSE($AZ$1,'Tính'!$E$4,'Tính'!$J$4,'Tính'!$O$4,'Tính'!$T$4)) | BE4: =IF($AZ$1=0,'Tính'!$AB$4,CHOOSE($AZ$1,'Tính'!$I$4,'Tính'!$N$4,'Tính'!$S$4,'Tính'!$X$4)) | BF4: =IF($AZ$1=0,'Tính'!$AA$4,CHOOSE($AZ$1,'Tính'!$H$4,'Tính'!$M$4,'Tính'!$R$4,'Tính'!$W$4)) | BG4: =IF(BC4>0,BD4/NgayQua*SoNgay/BC4,IF(BD4>0,1,0)) | BH4: =IF(CoRTNhom=1,IF(BC4>0,(BD4+BF4)/(NgayQua+1)*SoNgay/BC4,IF(BD4+BF4>0,1,0)),BG4) | BI4: =IF(BA4="",-1,IF(BB4="Chính",1000,0)+BG4+(20-2)/100000) | BJ4: =IF(LARGE($BI$3:$BI$22,2)<0,"",MATCH(LARGE($BI$3:$BI$22,2),$BI$3:$BI$22,0)) | CA4: 2 | CB4: =IF('Tính'!B40="",0,IF(OR($AZ$1=0,'Tính'!D40=$AZ$1),1,0)) | CC4: =IF(CB4=1,'Tính'!M40+1+(45-2)/1000000,-1) | CD4: =IF(LARGE($CC$3:$CC$47,2)<0,"",MATCH(LARGE($CC$3:$CC$47,2),$CC$3:$CC$47,0))
B5: Loại | C5: Target | D5: Thực hiện | E5: Tỉ lệ | F5: Dự kiến | H5: =IF($CD$3="","",1) | I5: =IF($CD$3="","",IF($CD$3="","",INDEX('Tính'!$F$39:$F$83,$CD$3))&" · "&IF($CD$3="","",INDEX('Tính'!$O$39:$O$83,$CD$3))) | J5: =IF($CD$3="","",INDEX('Tính'!$J$39:$J$83,$CD$3)) | K5: =IF($CD$3="","",INDEX('Tính'!$K$39:$K$83,$CD$3)) | L5: =IF($CD$3="","",INDEX('Tính'!$N$39:$N$83,$CD$3)) | M5: =IF($CD$3="","",INDEX('Tính'!$M$39:$M$83,$CD$3)) | N5: =IF($CD$3="","",IF($CD$3="","",INDEX('Tính'!$P$39:$P$83,$CD$3))&"/"&COUNTIF($BA$3:$BA$22,"?*")) | BA5: ='Tính'!B5 | BB5: ='Tính'!D5 | BC5: =IF($AZ$1=0,'Tính'!$Z$5,CHOOSE($AZ$1,'Tính'!$G$5,'Tính'!$L$5,'Tính'!$Q$5,'Tính'!$V$5)) | BD5: =IF($AZ$1=0,'Tính'!$Y$5,CHOOSE($AZ$1,'Tính'!$E$5,'Tính'!$J$5,'Tính'!$O$5,'Tính'!$T$5)) | BE5: =IF($AZ$1=0,'Tính'!$AB$5,CHOOSE($AZ$1,'Tính'!$I$5,'Tính'!$N$5,'Tính'!$S$5,'Tính'!$X$5)) | BF5: =IF($AZ$1=0,'Tính'!$AA$5,CHOOSE($AZ$1,'Tính'!$H$5,'Tính'!$M$5,'Tính'!$R$5,'Tính'!$W$5)) | BG5: =IF(BC5>0,BD5/NgayQua*SoNgay/BC5,IF(BD5>0,1,0)) | BH5: =IF(CoRTNhom=1,IF(BC5>0,(BD5+BF5)/(NgayQua+1)*SoNgay/BC5,IF(BD5+BF5>0,1,0)),BG5) | BI5: =IF(BA5="",-1,IF(BB5="Chính",1000,0)+BG5+(20-3)/100000) | BJ5: =IF(LARGE($BI$3:$BI$22,3)<0,"",MATCH(LARGE($BI$3:$BI$22,3),$BI$3:$BI$22,0)) | CA5: 3 | CB5: =IF('Tính'!B41="",0,IF(OR($AZ$1=0,'Tính'!D41=$AZ$1),1,0)) | CC5: =IF(CB5=1,'Tính'!M41+1+(45-3)/1000000,-1) | CD5: =IF(LARGE($CC$3:$CC$47,3)<0,"",MATCH(LARGE($CC$3:$CC$47,3),$CC$3:$CC$47,0))
A6: Doanh thu | C6: =INDEX('Tính'!$D$31:$D$35,IF($AZ$1=0,5,$AZ$1)) | D6: =INDEX('Tính'!$F$31:$F$35,IF($AZ$1=0,5,$AZ$1)) | E6: =IF(C6>0,D6/C6,0) | F6: =IF(C6>0,D6/NgayQua*SoNgay/C6,0) | H6: =IF($CD$4="","",2) | I6: =IF($CD$4="","",IF($CD$4="","",INDEX('Tính'!$F$39:$F$83,$CD$4))&" · "&IF($CD$4="","",INDEX('Tính'!$O$39:$O$83,$CD$4))) | J6: =IF($CD$4="","",INDEX('Tính'!$J$39:$J$83,$CD$4)) | K6: =IF($CD$4="","",INDEX('Tính'!$K$39:$K$83,$CD$4)) | L6: =IF($CD$4="","",INDEX('Tính'!$N$39:$N$83,$CD$4)) | M6: =IF($CD$4="","",INDEX('Tính'!$M$39:$M$83,$CD$4)) | N6: =IF($CD$4="","",IF($CD$4="","",INDEX('Tính'!$P$39:$P$83,$CD$4))&"/"&COUNTIF($BA$3:$BA$22,"?*")) | BA6: ='Tính'!B6 | BB6: ='Tính'!D6 | BC6: =IF($AZ$1=0,'Tính'!$Z$6,CHOOSE($AZ$1,'Tính'!$G$6,'Tính'!$L$6,'Tính'!$Q$6,'Tính'!$V$6)) | BD6: =IF($AZ$1=0,'Tính'!$Y$6,CHOOSE($AZ$1,'Tính'!$E$6,'Tính'!$J$6,'Tính'!$O$6,'Tính'!$T$6)) | BE6: =IF($AZ$1=0,'Tính'!$AB$6,CHOOSE($AZ$1,'Tính'!$I$6,'Tính'!$N$6,'Tính'!$S$6,'Tính'!$X$6)) | BF6: =IF($AZ$1=0,'Tính'!$AA$6,CHOOSE($AZ$1,'Tính'!$H$6,'Tính'!$M$6,'Tính'!$R$6,'Tính'!$W$6)) | BG6: =IF(BC6>0,BD6/NgayQua*SoNgay/BC6,IF(BD6>0,1,0)) | BH6: =IF(CoRTNhom=1,IF(BC6>0,(BD6+BF6)/(NgayQua+1)*SoNgay/BC6,IF(BD6+BF6>0,1,0)),BG6) | BI6: =IF(BA6="",-1,IF(BB6="Chính",1000,0)+BG6+(20-4)/100000) | BJ6: =IF(LARGE($BI$3:$BI$22,4)<0,"",MATCH(LARGE($BI$3:$BI$22,4),$BI$3:$BI$22,0)) | CA6: 4 | CB6: =IF('Tính'!B42="",0,IF(OR($AZ$1=0,'Tính'!D42=$AZ$1),1,0)) | CC6: =IF(CB6=1,'Tính'!M42+1+(45-4)/1000000,-1) | CD6: =IF(LARGE($CC$3:$CC$47,4)<0,"",MATCH(LARGE($CC$3:$CC$47,4),$CC$3:$CC$47,0))
A7: Trả chậm | C7: =MucTieuTC | D7: =INDEX('Tính'!$H$31:$H$35,IF($AZ$1=0,5,$AZ$1)) | E7: =IF(D7>=C7,"Đạt","Chưa đạt") | H7: =IF($CD$5="","",3) | I7: =IF($CD$5="","",IF($CD$5="","",INDEX('Tính'!$F$39:$F$83,$CD$5))&" · "&IF($CD$5="","",INDEX('Tính'!$O$39:$O$83,$CD$5))) | J7: =IF($CD$5="","",INDEX('Tính'!$J$39:$J$83,$CD$5)) | K7: =IF($CD$5="","",INDEX('Tính'!$K$39:$K$83,$CD$5)) | L7: =IF($CD$5="","",INDEX('Tính'!$N$39:$N$83,$CD$5)) | M7: =IF($CD$5="","",INDEX('Tính'!$M$39:$M$83,$CD$5)) | N7: =IF($CD$5="","",IF($CD$5="","",INDEX('Tính'!$P$39:$P$83,$CD$5))&"/"&COUNTIF($BA$3:$BA$22,"?*")) | BA7: ='Tính'!B7 | BB7: ='Tính'!D7 | BC7: =IF($AZ$1=0,'Tính'!$Z$7,CHOOSE($AZ$1,'Tính'!$G$7,'Tính'!$L$7,'Tính'!$Q$7,'Tính'!$V$7)) | BD7: =IF($AZ$1=0,'Tính'!$Y$7,CHOOSE($AZ$1,'Tính'!$E$7,'Tính'!$J$7,'Tính'!$O$7,'Tính'!$T$7)) | BE7: =IF($AZ$1=0,'Tính'!$AB$7,CHOOSE($AZ$1,'Tính'!$I$7,'Tính'!$N$7,'Tính'!$S$7,'Tính'!$X$7)) | BF7: =IF($AZ$1=0,'Tính'!$AA$7,CHOOSE($AZ$1,'Tính'!$H$7,'Tính'!$M$7,'Tính'!$R$7,'Tính'!$W$7)) | BG7: =IF(BC7>0,BD7/NgayQua*SoNgay/BC7,IF(BD7>0,1,0)) | BH7: =IF(CoRTNhom=1,IF(BC7>0,(BD7+BF7)/(NgayQua+1)*SoNgay/BC7,IF(BD7+BF7>0,1,0)),BG7) | BI7: =IF(BA7="",-1,IF(BB7="Chính",1000,0)+BG7+(20-5)/100000) | BJ7: =IF(LARGE($BI$3:$BI$22,5)<0,"",MATCH(LARGE($BI$3:$BI$22,5),$BI$3:$BI$22,0)) | CA7: 5 | CB7: =IF('Tính'!B43="",0,IF(OR($AZ$1=0,'Tính'!D43=$AZ$1),1,0)) | CC7: =IF(CB7=1,'Tính'!M43+1+(45-5)/1000000,-1) | CD7: =IF(LARGE($CC$3:$CC$47,5)<0,"",MATCH(LARGE($CC$3:$CC$47,5),$CC$3:$CC$47,0))
A8: ="SL nhóm: "&COUNTIF($BA$3:$BA$22,"?*") | C8: ="Chính đạt: "&COUNTIFS(B10:B29,"Chính",F10:F29,">=0.995")&"/"&COUNTIF(B10:B29,"Chính") | E8: ="Vượt trội: "&COUNTIFS(B10:B29,"Vượt trội",F10:F29,">=0.995")&"/"&COUNTIF(B10:B29,"Vượt trội") | H8: =IF($CD$6="","",4) | I8: =IF($CD$6="","",IF($CD$6="","",INDEX('Tính'!$F$39:$F$83,$CD$6))&" · "&IF($CD$6="","",INDEX('Tính'!$O$39:$O$83,$CD$6))) | J8: =IF($CD$6="","",INDEX('Tính'!$J$39:$J$83,$CD$6)) | K8: =IF($CD$6="","",INDEX('Tính'!$K$39:$K$83,$CD$6)) | L8: =IF($CD$6="","",INDEX('Tính'!$N$39:$N$83,$CD$6)) | M8: =IF($CD$6="","",INDEX('Tính'!$M$39:$M$83,$CD$6)) | N8: =IF($CD$6="","",IF($CD$6="","",INDEX('Tính'!$P$39:$P$83,$CD$6))&"/"&COUNTIF($BA$3:$BA$22,"?*")) | BA8: ='Tính'!B8 | BB8: ='Tính'!D8 | BC8: =IF($AZ$1=0,'Tính'!$Z$8,CHOOSE($AZ$1,'Tính'!$G$8,'Tính'!$L$8,'Tính'!$Q$8,'Tính'!$V$8)) | BD8: =IF($AZ$1=0,'Tính'!$Y$8,CHOOSE($AZ$1,'Tính'!$E$8,'Tính'!$J$8,'Tính'!$O$8,'Tính'!$T$8)) | BE8: =IF($AZ$1=0,'Tính'!$AB$8,CHOOSE($AZ$1,'Tính'!$I$8,'Tính'!$N$8,'Tính'!$S$8,'Tính'!$X$8)) | BF8: =IF($AZ$1=0,'Tính'!$AA$8,CHOOSE($AZ$1,'Tính'!$H$8,'Tính'!$M$8,'Tính'!$R$8,'Tính'!$W$8)) | BG8: =IF(BC8>0,BD8/NgayQua*SoNgay/BC8,IF(BD8>0,1,0)) | BH8: =IF(CoRTNhom=1,IF(BC8>0,(BD8+BF8)/(NgayQua+1)*SoNgay/BC8,IF(BD8+BF8>0,1,0)),BG8) | BI8: =IF(BA8="",-1,IF(BB8="Chính",1000,0)+BG8+(20-6)/100000) | BJ8: =IF(LARGE($BI$3:$BI$22,6)<0,"",MATCH(LARGE($BI$3:$BI$22,6),$BI$3:$BI$22,0)) | CA8: 6 | CB8: =IF('Tính'!B44="",0,IF(OR($AZ$1=0,'Tính'!D44=$AZ$1),1,0)) | CC8: =IF(CB8=1,'Tính'!M44+1+(45-6)/1000000,-1) | CD8: =IF(LARGE($CC$3:$CC$47,6)<0,"",MATCH(LARGE($CC$3:$CC$47,6),$CC$3:$CC$47,0))
A9: Nhóm hàng | B9: Loại | C9: Target | D9: Thực hiện | E9: % Hiện tại | F9: Dự kiến ▼ | H9: =IF($CD$7="","",5) | I9: =IF($CD$7="","",IF($CD$7="","",INDEX('Tính'!$F$39:$F$83,$CD$7))&" · "&IF($CD$7="","",INDEX('Tính'!$O$39:$O$83,$CD$7))) | J9: =IF($CD$7="","",INDEX('Tính'!$J$39:$J$83,$CD$7)) | K9: =IF($CD$7="","",INDEX('Tính'!$K$39:$K$83,$CD$7)) | L9: =IF($CD$7="","",INDEX('Tính'!$N$39:$N$83,$CD$7)) | M9: =IF($CD$7="","",INDEX('Tính'!$M$39:$M$83,$CD$7)) | N9: =IF($CD$7="","",IF($CD$7="","",INDEX('Tính'!$P$39:$P$83,$CD$7))&"/"&COUNTIF($BA$3:$BA$22,"?*")) | BA9: ='Tính'!B9 | BB9: ='Tính'!D9 | BC9: =IF($AZ$1=0,'Tính'!$Z$9,CHOOSE($AZ$1,'Tính'!$G$9,'Tính'!$L$9,'Tính'!$Q$9,'Tính'!$V$9)) | BD9: =IF($AZ$1=0,'Tính'!$Y$9,CHOOSE($AZ$1,'Tính'!$E$9,'Tính'!$J$9,'Tính'!$O$9,'Tính'!$T$9)) | BE9: =IF($AZ$1=0,'Tính'!$AB$9,CHOOSE($AZ$1,'Tính'!$I$9,'Tính'!$N$9,'Tính'!$S$9,'Tính'!$X$9)) | BF9: =IF($AZ$1=0,'Tính'!$AA$9,CHOOSE($AZ$1,'Tính'!$H$9,'Tính'!$M$9,'Tính'!$R$9,'Tính'!$W$9)) | BG9: =IF(BC9>0,BD9/NgayQua*SoNgay/BC9,IF(BD9>0,1,0)) | BH9: =IF(CoRTNhom=1,IF(BC9>0,(BD9+BF9)/(NgayQua+1)*SoNgay/BC9,IF(BD9+BF9>0,1,0)),BG9) | BI9: =IF(BA9="",-1,IF(BB9="Chính",1000,0)+BG9+(20-7)/100000) | BJ9: =IF(LARGE($BI$3:$BI$22,7)<0,"",MATCH(LARGE($BI$3:$BI$22,7),$BI$3:$BI$22,0)) | CA9: 7 | CB9: =IF('Tính'!B45="",0,IF(OR($AZ$1=0,'Tính'!D45=$AZ$1),1,0)) | CC9: =IF(CB9=1,'Tính'!M45+1+(45-7)/1000000,-1) | CD9: =IF(LARGE($CC$3:$CC$47,7)<0,"",MATCH(LARGE($CC$3:$CC$47,7),$CC$3:$CC$47,0))
A10: =IF($BJ$3="","",INDEX($BA$3:$BA$22,$BJ$3)) | B10: =IF($BJ$3="","",INDEX($BB$3:$BB$22,$BJ$3)) | C10: =IF($BJ$3="","",INDEX($BC$3:$BC$22,$BJ$3)) | D10: =IF($BJ$3="","",INDEX($BD$3:$BD$22,$BJ$3)) | E10: =IF(A10="","",IF(C10>0,D10/C10,1)) | F10: =IF($BJ$3="","",INDEX($BG$3:$BG$22,$BJ$3)) | H10: =IF($CD$8="","",6) | I10: =IF($CD$8="","",IF($CD$8="","",INDEX('Tính'!$F$39:$F$83,$CD$8))&" · "&IF($CD$8="","",INDEX('Tính'!$O$39:$O$83,$CD$8))) | J10: =IF($CD$8="","",INDEX('Tính'!$J$39:$J$83,$CD$8)) | K10: =IF($CD$8="","",INDEX('Tính'!$K$39:$K$83,$CD$8)) | L10: =IF($CD$8="","",INDEX('Tính'!$N$39:$N$83,$CD$8)) | M10: =IF($CD$8="","",INDEX('Tính'!$M$39:$M$83,$CD$8)) | N10: =IF($CD$8="","",IF($CD$8="","",INDEX('Tính'!$P$39:$P$83,$CD$8))&"/"&COUNTIF($BA$3:$BA$22,"?*")) | BA10: ='Tính'!B10 | BB10: ='Tính'!D10 | BC10: =IF($AZ$1=0,'Tính'!$Z$10,CHOOSE($AZ$1,'Tính'!$G$10,'Tính'!$L$10,'Tính'!$Q$10,'Tính'!$V$10)) | BD10: =IF($AZ$1=0,'Tính'!$Y$10,CHOOSE($AZ$1,'Tính'!$E$10,'Tính'!$J$10,'Tính'!$O$10,'Tính'!$T$10)) | BE10: =IF($AZ$1=0,'Tính'!$AB$10,CHOOSE($AZ$1,'Tính'!$I$10,'Tính'!$N$10,'Tính'!$S$10,'Tính'!$X$10)) | BF10: =IF($AZ$1=0,'Tính'!$AA$10,CHOOSE($AZ$1,'Tính'!$H$10,'Tính'!$M$10,'Tính'!$R$10,'Tính'!$W$10)) | BG10: =IF(BC10>0,BD10/NgayQua*SoNgay/BC10,IF(BD10>0,1,0)) | BH10: =IF(CoRTNhom=1,IF(BC10>0,(BD10+BF10)/(NgayQua+1)*SoNgay/BC10,IF(BD10+BF10>0,1,0)),BG10) | BI10: =IF(BA10="",-1,IF(BB10="Chính",1000,0)+BG10+(20-8)/100000) | BJ10: =IF(LARGE($BI$3:$BI$22,8)<0,"",MATCH(LARGE($BI$3:$BI$22,8),$BI$3:$BI$22,0)) | CA10: 8 | CB10: =IF('Tính'!B46="",0,IF(OR($AZ$1=0,'Tính'!D46=$AZ$1),1,0)) | CC10: =IF(CB10=1,'Tính'!M46+1+(45-8)/1000000,-1) | CD10: =IF(LARGE($CC$3:$CC$47,8)<0,"",MATCH(LARGE($CC$3:$CC$47,8),$CC$3:$CC$47,0))
A11: =IF($BJ$4="","",INDEX($BA$3:$BA$22,$BJ$4)) | B11: =IF($BJ$4="","",INDEX($BB$3:$BB$22,$BJ$4)) | C11: =IF($BJ$4="","",INDEX($BC$3:$BC$22,$BJ$4)) | D11: =IF($BJ$4="","",INDEX($BD$3:$BD$22,$BJ$4)) | E11: =IF(A11="","",IF(C11>0,D11/C11,1)) | F11: =IF($BJ$4="","",INDEX($BG$3:$BG$22,$BJ$4)) | H11: =IF($CD$9="","",7) | I11: =IF($CD$9="","",IF($CD$9="","",INDEX('Tính'!$F$39:$F$83,$CD$9))&" · "&IF($CD$9="","",INDEX('Tính'!$O$39:$O$83,$CD$9))) | J11: =IF($CD$9="","",INDEX('Tính'!$J$39:$J$83,$CD$9)) | K11: =IF($CD$9="","",INDEX('Tính'!$K$39:$K$83,$CD$9)) | L11: =IF($CD$9="","",INDEX('Tính'!$N$39:$N$83,$CD$9)) | M11: =IF($CD$9="","",INDEX('Tính'!$M$39:$M$83,$CD$9)) | N11: =IF($CD$9="","",IF($CD$9="","",INDEX('Tính'!$P$39:$P$83,$CD$9))&"/"&COUNTIF($BA$3:$BA$22,"?*")) | BA11: ='Tính'!B11 | BB11: ='Tính'!D11 | BC11: =IF($AZ$1=0,'Tính'!$Z$11,CHOOSE($AZ$1,'Tính'!$G$11,'Tính'!$L$11,'Tính'!$Q$11,'Tính'!$V$11)) | BD11: =IF($AZ$1=0,'Tính'!$Y$11,CHOOSE($AZ$1,'Tính'!$E$11,'Tính'!$J$11,'Tính'!$O$11,'Tính'!$T$11)) | BE11: =IF($AZ$1=0,'Tính'!$AB$11,CHOOSE($AZ$1,'Tính'!$I$11,'Tính'!$N$11,'Tính'!$S$11,'Tính'!$X$11)) | BF11: =IF($AZ$1=0,'Tính'!$AA$11,CHOOSE($AZ$1,'Tính'!$H$11,'Tính'!$M$11,'Tính'!$R$11,'Tính'!$W$11)) | BG11: =IF(BC11>0,BD11/NgayQua*SoNgay/BC11,IF(BD11>0,1,0)) | BH11: =IF(CoRTNhom=1,IF(BC11>0,(BD11+BF11)/(NgayQua+1)*SoNgay/BC11,IF(BD11+BF11>0,1,0)),BG11) | BI11: =IF(BA11="",-1,IF(BB11="Chính",1000,0)+BG11+(20-9)/100000) | BJ11: =IF(LARGE($BI$3:$BI$22,9)<0,"",MATCH(LARGE($BI$3:$BI$22,9),$BI$3:$BI$22,0)) | CA11: 9 | CB11: =IF('Tính'!B47="",0,IF(OR($AZ$1=0,'Tính'!D47=$AZ$1),1,0)) | CC11: =IF(CB11=1,'Tính'!M47+1+(45-9)/1000000,-1) | CD11: =IF(LARGE($CC$3:$CC$47,9)<0,"",MATCH(LARGE($CC$3:$CC$47,9),$CC$3:$CC$47,0))
A12: =IF($BJ$5="","",INDEX($BA$3:$BA$22,$BJ$5)) | B12: =IF($BJ$5="","",INDEX($BB$3:$BB$22,$BJ$5)) | C12: =IF($BJ$5="","",INDEX($BC$3:$BC$22,$BJ$5)) | D12: =IF($BJ$5="","",INDEX($BD$3:$BD$22,$BJ$5)) | E12: =IF(A12="","",IF(C12>0,D12/C12,1)) | F12: =IF($BJ$5="","",INDEX($BG$3:$BG$22,$BJ$5)) | H12: =IF($CD$10="","",8) | I12: =IF($CD$10="","",IF($CD$10="","",INDEX('Tính'!$F$39:$F$83,$CD$10))&" · "&IF($CD$10="","",INDEX('Tính'!$O$39:$O$83,$CD$10))) | J12: =IF($CD$10="","",INDEX('Tính'!$J$39:$J$83,$CD$10)) | K12: =IF($CD$10="","",INDEX('Tính'!$K$39:$K$83,$CD$10)) | L12: =IF($CD$10="","",INDEX('Tính'!$N$39:$N$83,$CD$10)) | M12: =IF($CD$10="","",INDEX('Tính'!$M$39:$M$83,$CD$10)) | N12: =IF($CD$10="","",IF($CD$10="","",INDEX('Tính'!$P$39:$P$83,$CD$10))&"/"&COUNTIF($BA$3:$BA$22,"?*")) | BA12: ='Tính'!B12 | BB12: ='Tính'!D12 | BC12: =IF($AZ$1=0,'Tính'!$Z$12,CHOOSE($AZ$1,'Tính'!$G$12,'Tính'!$L$12,'Tính'!$Q$12,'Tính'!$V$12)) | BD12: =IF($AZ$1=0,'Tính'!$Y$12,CHOOSE($AZ$1,'Tính'!$E$12,'Tính'!$J$12,'Tính'!$O$12,'Tính'!$T$12)) | BE12: =IF($AZ$1=0,'Tính'!$AB$12,CHOOSE($AZ$1,'Tính'!$I$12,'Tính'!$N$12,'Tính'!$S$12,'Tính'!$X$12)) | BF12: =IF($AZ$1=0,'Tính'!$AA$12,CHOOSE($AZ$1,'Tính'!$H$12,'Tính'!$M$12,'Tính'!$R$12,'Tính'!$W$12)) | BG12: =IF(BC12>0,BD12/NgayQua*SoNgay/BC12,IF(BD12>0,1,0)) | BH12: =IF(CoRTNhom=1,IF(BC12>0,(BD12+BF12)/(NgayQua+1)*SoNgay/BC12,IF(BD12+BF12>0,1,0)),BG12) | BI12: =IF(BA12="",-1,IF(BB12="Chính",1000,0)+BG12+(20-10)/100000) | BJ12: =IF(LARGE($BI$3:$BI$22,10)<0,"",MATCH(LARGE($BI$3:$BI$22,10),$BI$3:$BI$22,0)) | CA12: 10 | CB12: =IF('Tính'!B48="",0,IF(OR($AZ$1=0,'Tính'!D48=$AZ$1),1,0)) | CC12: =IF(CB12=1,'Tính'!M48+1+(45-10)/1000000,-1) | CD12: =IF(LARGE($CC$3:$CC$47,10)<0,"",MATCH(LARGE($CC$3:$CC$47,10),$CC$3:$CC$47,0))
A13: =IF($BJ$6="","",INDEX($BA$3:$BA$22,$BJ$6)) | B13: =IF($BJ$6="","",INDEX($BB$3:$BB$22,$BJ$6)) | C13: =IF($BJ$6="","",INDEX($BC$3:$BC$22,$BJ$6)) | D13: =IF($BJ$6="","",INDEX($BD$3:$BD$22,$BJ$6)) | E13: =IF(A13="","",IF(C13>0,D13/C13,1)) | F13: =IF($BJ$6="","",INDEX($BG$3:$BG$22,$BJ$6)) | H13: =IF($CD$11="","",9) | I13: =IF($CD$11="","",IF($CD$11="","",INDEX('Tính'!$F$39:$F$83,$CD$11))&" · "&IF($CD$11="","",INDEX('Tính'!$O$39:$O$83,$CD$11))) | J13: =IF($CD$11="","",INDEX('Tính'!$J$39:$J$83,$CD$11)) | K13: =IF($CD$11="","",INDEX('Tính'!$K$39:$K$83,$CD$11)) | L13: =IF($CD$11="","",INDEX('Tính'!$N$39:$N$83,$CD$11)) | M13: =IF($CD$11="","",INDEX('Tính'!$M$39:$M$83,$CD$11)) | N13: =IF($CD$11="","",IF($CD$11="","",INDEX('Tính'!$P$39:$P$83,$CD$11))&"/"&COUNTIF($BA$3:$BA$22,"?*")) | BA13: ='Tính'!B13 | BB13: ='Tính'!D13 | BC13: =IF($AZ$1=0,'Tính'!$Z$13,CHOOSE($AZ$1,'Tính'!$G$13,'Tính'!$L$13,'Tính'!$Q$13,'Tính'!$V$13)) | BD13: =IF($AZ$1=0,'Tính'!$Y$13,CHOOSE($AZ$1,'Tính'!$E$13,'Tính'!$J$13,'Tính'!$O$13,'Tính'!$T$13)) | BE13: =IF($AZ$1=0,'Tính'!$AB$13,CHOOSE($AZ$1,'Tính'!$I$13,'Tính'!$N$13,'Tính'!$S$13,'Tính'!$X$13)) | BF13: =IF($AZ$1=0,'Tính'!$AA$13,CHOOSE($AZ$1,'Tính'!$H$13,'Tính'!$M$13,'Tính'!$R$13,'Tính'!$W$13)) | BG13: =IF(BC13>0,BD13/NgayQua*SoNgay/BC13,IF(BD13>0,1,0)) | BH13: =IF(CoRTNhom=1,IF(BC13>0,(BD13+BF13)/(NgayQua+1)*SoNgay/BC13,IF(BD13+BF13>0,1,0)),BG13) | BI13: =IF(BA13="",-1,IF(BB13="Chính",1000,0)+BG13+(20-11)/100000) | BJ13: =IF(LARGE($BI$3:$BI$22,11)<0,"",MATCH(LARGE($BI$3:$BI$22,11),$BI$3:$BI$22,0)) | CA13: 11 | CB13: =IF('Tính'!B49="",0,IF(OR($AZ$1=0,'Tính'!D49=$AZ$1),1,0)) | CC13: =IF(CB13=1,'Tính'!M49+1+(45-11)/1000000,-1) | CD13: =IF(LARGE($CC$3:$CC$47,11)<0,"",MATCH(LARGE($CC$3:$CC$47,11),$CC$3:$CC$47,0))
A14: =IF($BJ$7="","",INDEX($BA$3:$BA$22,$BJ$7)) | B14: =IF($BJ$7="","",INDEX($BB$3:$BB$22,$BJ$7)) | C14: =IF($BJ$7="","",INDEX($BC$3:$BC$22,$BJ$7)) | D14: =IF($BJ$7="","",INDEX($BD$3:$BD$22,$BJ$7)) | E14: =IF(A14="","",IF(C14>0,D14/C14,1)) | F14: =IF($BJ$7="","",INDEX($BG$3:$BG$22,$BJ$7)) | H14: =IF($CD$12="","",10) | I14: =IF($CD$12="","",IF($CD$12="","",INDEX('Tính'!$F$39:$F$83,$CD$12))&" · "&IF($CD$12="","",INDEX('Tính'!$O$39:$O$83,$CD$12))) | J14: =IF($CD$12="","",INDEX('Tính'!$J$39:$J$83,$CD$12)) | K14: =IF($CD$12="","",INDEX('Tính'!$K$39:$K$83,$CD$12)) | L14: =IF($CD$12="","",INDEX('Tính'!$N$39:$N$83,$CD$12)) | M14: =IF($CD$12="","",INDEX('Tính'!$M$39:$M$83,$CD$12)) | N14: =IF($CD$12="","",IF($CD$12="","",INDEX('Tính'!$P$39:$P$83,$CD$12))&"/"&COUNTIF($BA$3:$BA$22,"?*")) | BA14: ='Tính'!B14 | BB14: ='Tính'!D14 | BC14: =IF($AZ$1=0,'Tính'!$Z$14,CHOOSE($AZ$1,'Tính'!$G$14,'Tính'!$L$14,'Tính'!$Q$14,'Tính'!$V$14)) | BD14: =IF($AZ$1=0,'Tính'!$Y$14,CHOOSE($AZ$1,'Tính'!$E$14,'Tính'!$J$14,'Tính'!$O$14,'Tính'!$T$14)) | BE14: =IF($AZ$1=0,'Tính'!$AB$14,CHOOSE($AZ$1,'Tính'!$I$14,'Tính'!$N$14,'Tính'!$S$14,'Tính'!$X$14)) | BF14: =IF($AZ$1=0,'Tính'!$AA$14,CHOOSE($AZ$1,'Tính'!$H$14,'Tính'!$M$14,'Tính'!$R$14,'Tính'!$W$14)) | BG14: =IF(BC14>0,BD14/NgayQua*SoNgay/BC14,IF(BD14>0,1,0)) | BH14: =IF(CoRTNhom=1,IF(BC14>0,(BD14+BF14)/(NgayQua+1)*SoNgay/BC14,IF(BD14+BF14>0,1,0)),BG14) | BI14: =IF(BA14="",-1,IF(BB14="Chính",1000,0)+BG14+(20-12)/100000) | BJ14: =IF(LARGE($BI$3:$BI$22,12)<0,"",MATCH(LARGE($BI$3:$BI$22,12),$BI$3:$BI$22,0)) | CA14: 12 | CB14: =IF('Tính'!B50="",0,IF(OR($AZ$1=0,'Tính'!D50=$AZ$1),1,0)) | CC14: =IF(CB14=1,'Tính'!M50+1+(45-12)/1000000,-1) | CD14: =IF(LARGE($CC$3:$CC$47,12)<0,"",MATCH(LARGE($CC$3:$CC$47,12),$CC$3:$CC$47,0))
